<?xml version="1.0"?>
<robot name="g1_29dof_rev_1_0">

  <link name="world"/>
  <link name="pelvis">
    <inertial>
      <origin xyz="0 0 -0.07605" rpy="0 -0.00079829608 0"/>
      <mass value="3.813"/>
      <inertia ixx="0.010549" iyy="0.0093089" izz="0.0079184" ixy="0" ixz="0" iyz="0"/>
    </inertial>
    <visual>
      <origin xyz="0 0 0" rpy="0 0 0"/>
      <geometry>
        <mesh filename="package://g1_description/meshes/pelvis.STL"/>
      </geometry>
      <material name="mesh_mat">
        <color rgba="0.200 0.200 0.200 1.000"/>
      </material>
    </visual>
  </link>
  <link name="pelvis_contour_link">
    <inertial>
      <origin xyz="0 0 0" rpy="0 0 0"/>
      <mass value="0.001"/>
      <inertia ixx="1e-07" iyy="1e-07" izz="1e-07" ixy="0" ixz="0" iyz="0"/>
    </inertial>
    <visual>
      <origin xyz="0 0 0" rpy="0 0 0"/>
      <geometry>
        <mesh filename="package://g1_description/meshes/pelvis_contour_link.STL"/>
      </geometry>
      <material name="mesh_mat">
        <color rgba="0.700 0.700 0.700 1.000"/>
      </material>
    </visual>
  </link>
  <link name="left_hip_pitch_link">
    <inertial>
      <origin xyz="0.002741 0.047791 -0.02606" rpy="0.5988169 0.040081009 0.075444907"/>
      <mass value="1.35"/>
      <inertia ixx="0.00181517" iyy="0.00153422" izz="0.00116212" ixy="0" ixz="0" iyz="0"/>
    </inertial>
    <visual>
      <origin xyz="0 0 0" rpy="0 0 0"/>
      <geometry>
        <mesh filename="package://g1_description/meshes/left_hip_pitch_link.STL"/>
      </geometry>
      <material name="mesh_mat">
        <color rgba="0.200 0.200 0.200 1.000"/>
      </material>
    </visual>
  </link>
  <link name="left_hip_roll_link">
    <inertial>
      <origin xyz="0.029812 -0.001045 -0.087934" rpy="-0.018174947 0.4137286 -0.086359021"/>
      <mass value="1.52"/>
      <inertia ixx="0.00254986" iyy="0.00241169" izz="0.00148755" ixy="0" ixz="0" iyz="0"/>
    </inertial>
    <visual>
      <origin xyz="0 0 0" rpy="0 0 0"/>
      <geometry>
        <mesh filename="package://g1_description/meshes/left_hip_roll_link.STL"/>
      </geometry>
      <material name="mesh_mat">
        <color rgba="0.700 0.700 0.700 1.000"/>
      </material>
    </visual>
  </link>
  <link name="left_hip_yaw_link">
    <inertial>
      <origin xyz="-0.057709 -0.010981 -0.15078" rpy="0.55409093 0.030596506 1.8013752"/>
      <mass value="1.702"/>
      <inertia ixx="0.00776166" iyy="0.00717575" izz="0.00160139" ixy="0" ixz="0" iyz="0"/>
    </inertial>
    <visual>
      <origin xyz="0 0 0" rpy="0 0 0"/>
      <geometry>
        <mesh filename="package://g1_description/meshes/left_hip_yaw_link.STL"/>
      </geometry>
      <material name="mesh_mat">
        <color rgba="0.700 0.700 0.700 1.000"/>
      </material>
    </visual>
    <collision>
      <origin xyz="-0.025 0 -0.1" rpy="0 0.52000101 0"/>
      <geometry>
        <cylinder radius="0.03" length="0.2"/>
      </geometry>
    </collision>
  </link>
  <link name="left_knee_link">
    <inertial>
      <origin xyz="0.005457 0.003964 -0.12074" rpy="-0.048519014 0.054292705 0.78329437"/>
      <mass value="1.932"/>
      <inertia ixx="0.0113804" iyy="0.0112778" izz="0.00146458" ixy="0" ixz="0" iyz="0"/>
    </inertial>
    <visual>
      <origin xyz="0 0 0" rpy="0 0 0"/>
      <geometry>
        <mesh filename="package://g1_description/meshes/left_knee_link.STL"/>
      </geometry>
      <material name="mesh_mat">
        <color rgba="0.700 0.700 0.700 1.000"/>
      </material>
    </visual>
    <collision>
      <origin xyz="0.007 0.005 -0.15" rpy="0 0 0"/>
      <geometry>
        <cylinder radius="0.03" length="0.15"/>
      </geometry>
    </collision>
  </link>
  <link name="left_ankle_pitch_link">
    <inertial>
      <origin xyz="-0.007269 0 0.011137" rpy="1.0987704 -0 1.5707964"/>
      <mass value="0.074"/>
      <inertia ixx="1.89e-05" iyy="1.40805e-05" izz="6.9195e-06" ixy="0" ixz="0" iyz="0"/>
    </inertial>
    <visual>
      <origin xyz="0 0 0" rpy="0 0 0"/>
      <geometry>
        <mesh filename="package://g1_description/meshes/left_ankle_pitch_link.STL"/>
      </geometry>
      <material name="mesh_mat">
        <color rgba="0.700 0.700 0.700 1.000"/>
      </material>
    </visual>
  </link>
  <link name="left_ankle_roll_link">
    <inertial>
      <origin xyz="0.026505 0 -0.016425" rpy="-3.1163588 -1.5093773 -0.025429463"/>
      <mass value="0.608"/>
      <inertia ixx="0.00167218" iyy="0.0016161" izz="0.000217621" ixy="0" ixz="0" iyz="0"/>
    </inertial>
    <visual>
      <origin xyz="0 0 0" rpy="0 0 0"/>
      <geometry>
        <mesh filename="package://g1_description/meshes/left_ankle_roll_link.STL"/>
      </geometry>
      <material name="mesh_mat">
        <color rgba="0.200 0.200 0.200 1.000"/>
      </material>
    </visual>
    <collision>
      <origin xyz="0.05 0.02 -0.02" rpy="3.1415927 1.5695351 3.1415927"/>
      <geometry>
        <cylinder radius="0.02" length="0.15"/>
      </geometry>
    </collision>
    <collision>
      <origin xyz="0.05 -0.02 -0.02" rpy="3.1415927 1.5695351 3.1415927"/>
      <geometry>
        <cylinder radius="0.02" length="0.15"/>
      </geometry>
    </collision>
  </link>
  <link name="left_toe_link">
  </link>
  <link name="right_hip_pitch_link">
    <inertial>
      <origin xyz="0.002741 -0.047791 -0.02606" rpy="-0.5988169 0.040081009 -0.075444907"/>
      <mass value="1.35"/>
      <inertia ixx="0.00181517" iyy="0.00153422" izz="0.00116212" ixy="0" ixz="0" iyz="0"/>
    </inertial>
    <visual>
      <origin xyz="0 0 0" rpy="0 0 0"/>
      <geometry>
        <mesh filename="package://g1_description/meshes/right_hip_pitch_link.STL"/>
      </geometry>
      <material name="mesh_mat">
        <color rgba="0.200 0.200 0.200 1.000"/>
      </material>
    </visual>
  </link>
  <link name="right_hip_roll_link">
    <inertial>
      <origin xyz="0.029812 0.001045 -0.087934" rpy="0.018174947 0.4137286 0.086359021"/>
      <mass value="1.52"/>
      <inertia ixx="0.00254986" iyy="0.00241169" izz="0.00148755" ixy="0" ixz="0" iyz="0"/>
    </inertial>
    <visual>
      <origin xyz="0 0 0" rpy="0 0 0"/>
      <geometry>
        <mesh filename="package://g1_description/meshes/right_hip_roll_link.STL"/>
      </geometry>
      <material name="mesh_mat">
        <color rgba="0.700 0.700 0.700 1.000"/>
      </material>
    </visual>
  </link>
  <link name="right_hip_yaw_link">
    <inertial>
      <origin xyz="-0.057709 0.010981 -0.15078" rpy="0.55409093 -0.030596506 1.340218"/>
      <mass value="1.702"/>
      <inertia ixx="0.00776166" iyy="0.00717575" izz="0.00160139" ixy="0" ixz="0" iyz="0"/>
    </inertial>
    <visual>
      <origin xyz="0 0 0" rpy="0 0 0"/>
      <geometry>
        <mesh filename="package://g1_description/meshes/right_hip_yaw_link.STL"/>
      </geometry>
      <material name="mesh_mat">
        <color rgba="0.700 0.700 0.700 1.000"/>
      </material>
    </visual>
    <collision>
      <origin xyz="-0.025 0 -0.1" rpy="0 0.52000101 0"/>
      <geometry>
        <cylinder radius="0.03" length="0.2"/>
      </geometry>
    </collision>
  </link>
  <link name="right_knee_link">
    <inertial>
      <origin xyz="0.005457 -0.003964 -0.12074" rpy="0.054970801 0.047883497 -0.78317758"/>
      <mass value="1.932"/>
      <inertia ixx="0.011374" iyy="0.0112843" izz="0.00146452" ixy="0" ixz="0" iyz="0"/>
    </inertial>
    <visual>
      <origin xyz="0 0 0" rpy="0 0 0"/>
      <geometry>
        <mesh filename="package://g1_description/meshes/right_knee_link.STL"/>
      </geometry>
      <material name="mesh_mat">
        <color rgba="0.700 0.700 0.700 1.000"/>
      </material>
    </visual>
    <collision>
      <origin xyz="0.007 -0.005 -0.15" rpy="0 0 0"/>
      <geometry>
        <cylinder radius="0.03" length="0.15"/>
      </geometry>
    </collision>
  </link>
  <link name="right_ankle_pitch_link">
    <inertial>
      <origin xyz="-0.007269 0 0.011137" rpy="1.0987704 -0 1.5707964"/>
      <mass value="0.074"/>
      <inertia ixx="1.89e-05" iyy="1.40805e-05" izz="6.9195e-06" ixy="0" ixz="0" iyz="0"/>
    </inertial>
    <visual>
      <origin xyz="0 0 0" rpy="0 0 0"/>
      <geometry>
        <mesh filename="package://g1_description/meshes/right_ankle_pitch_link.STL"/>
      </geometry>
      <material name="mesh_mat">
        <color rgba="0.700 0.700 0.700 1.000"/>
      </material>
    </visual>
  </link>
  <link name="right_ankle_roll_link">
    <inertial>
      <origin xyz="0.026505 0 -0.016425" rpy="3.1163588 -1.5093773 0.025429463"/>
      <mass value="0.608"/>
      <inertia ixx="0.00167218" iyy="0.0016161" izz="0.000217621" ixy="0" ixz="0" iyz="0"/>
    </inertial>
    <visual>
      <origin xyz="0 0 0" rpy="0 0 0"/>
      <geometry>
        <mesh filename="package://g1_description/meshes/right_ankle_roll_link.STL"/>
      </geometry>
      <material name="mesh_mat">
        <color rgba="0.200 0.200 0.200 1.000"/>
      </material>
    </visual>
    <collision>
      <origin xyz="0.05 0.02 -0.02" rpy="3.1415927 1.5695351 3.1415927"/>
      <geometry>
        <cylinder radius="0.02" length="0.15"/>
      </geometry>
    </collision>
    <collision>
      <origin xyz="0.05 -0.02 -0.02" rpy="3.1415927 1.5695351 3.1415927"/>
      <geometry>
        <cylinder radius="0.02" length="0.15"/>
      </geometry>
    </collision>
  </link>
  <link name="right_toe_link">
  </link>
  <link name="waist_yaw_link">
    <inertial>
      <origin xyz="0.003494 0.000233 0.018034" rpy="-0.99228585 -1.4364729 -3.0710004"/>
      <mass value="0.214"/>
      <inertia ixx="0.000163531" iyy="0.000107714" izz="0.000102205" ixy="0" ixz="0" iyz="0"/>
    </inertial>
    <visual>
      <origin xyz="0 0 0" rpy="0 0 0"/>
      <geometry>
        <mesh filename="package://g1_description/meshes/waist_yaw_link_rev_1_0.STL"/>
      </geometry>
      <material name="mesh_mat">
        <color rgba="0.700 0.700 0.700 1.000"/>
      </material>
    </visual>
  </link>
  <link name="waist_roll_link">
    <inertial>
      <origin xyz="0 2.3e-05 0" rpy="1.5707963 -1.5707963 0"/>
      <mass value="0.086"/>
      <inertia ixx="8.245e-06" iyy="7.079e-06" izz="6.339e-06" ixy="0" ixz="0" iyz="0"/>
    </inertial>
    <visual>
      <origin xyz="0 0 0" rpy="0 0 0"/>
      <geometry>
        <mesh filename="package://g1_description/meshes/waist_roll_link_rev_1_0.STL"/>
      </geometry>
      <material name="mesh_mat">
        <color rgba="0.700 0.700 0.700 1.000"/>
      </material>
    </visual>
  </link>
  <link name="torso_link">
    <inertial>
      <origin xyz="0.000931 0.000346 0.15082" rpy="-0.00081035029 0.052845968 0.0028431448"/>
      <mass value="6.78"/>
      <inertia ixx="0.0591438" iyy="0.0470139" izz="0.0255583" ixy="0" ixz="0" iyz="0"/>
    </inertial>
    <visual>
      <origin xyz="0 0 0" rpy="0 0 0"/>
      <geometry>
        <mesh filename="package://g1_description/meshes/torso_link_rev_1_0.STL"/>
      </geometry>
      <material name="mesh_mat">
        <color rgba="0.700 0.700 0.700 1.000"/>
      </material>
    </visual>
    <collision>
      <origin xyz="0 0 0.1" rpy="0 0 0"/>
      <geometry>
        <cylinder radius="0.08" length="0.35"/>
      </geometry>
    </collision>
  </link>
  <link name="head_link">
    <inertial>
      <origin xyz="0.005267 0.000299 0.449869" rpy="0.03049523 0.00084290613 1.5955804"/>
      <mass value="1.036"/>
      <inertia ixx="0.00418528" iyy="0.00408711" izz="0.00180579" ixy="0" ixz="0" iyz="0"/>
    </inertial>
    <visual>
      <origin xyz="0 0 0" rpy="0 0 0"/>
      <geometry>
        <mesh filename="package://g1_description/meshes/head_link.STL"/>
      </geometry>
      <material name="mesh_mat">
        <color rgba="0.200 0.200 0.200 1.000"/>
      </material>
    </visual>
  </link>
  <link name="head_mocap">
  </link>
  <link name="neck_link">
    <visual>
      <origin xyz="0 0 0" rpy="0 0 0"/>
      <geometry>
        <mesh filename="package://g1_description/meshes/twist2_neck.obj"/>
      </geometry>
      <material name="mesh_mat">
        <color rgba="0.700 0.700 0.700 1.000"/>
      </material>
    </visual>
  </link>
  <link name="imu_in_torso">
  </link>
  <link name="left_shoulder_pitch_link">
    <inertial>
      <origin xyz="0 0.035892 -0.011628" rpy="-0.49834897 -0.46079175 1.7320732"/>
      <mass value="0.718"/>
      <inertia ixx="0.000465864" iyy="0.000432842" izz="0.000406394" ixy="0" ixz="0" iyz="0"/>
    </inertial>
    <visual>
      <origin xyz="0 0 0" rpy="0 0 0"/>
      <geometry>
        <mesh filename="package://g1_description/meshes/left_shoulder_pitch_link.STL"/>
      </geometry>
      <material name="mesh_mat">
        <color rgba="0.700 0.700 0.700 1.000"/>
      </material>
    </visual>
  </link>
  <link name="left_shoulder_roll_link">
    <inertial>
      <origin xyz="-0.000227 0.00727 -0.063243" rpy="-0.037659009 0.01800455 1.5865094"/>
      <mass value="0.643"/>
      <inertia ixx="0.000691311" iyy="0.000618011" izz="0.000388977" ixy="0" ixz="0" iyz="0"/>
    </inertial>
    <visual>
      <origin xyz="0 0 0" rpy="0 0 0"/>
      <geometry>
        <mesh filename="package://g1_description/meshes/left_shoulder_roll_link.STL"/>
      </geometry>
      <material name="mesh_mat">
        <color rgba="0.700 0.700 0.700 1.000"/>
      </material>
    </visual>
    <collision>
      <origin xyz="-0.004 0.006 -0.053" rpy="0 0 0"/>
      <geometry>
        <cylinder radius="0.03" length="0.03"/>
      </geometry>
    </collision>
  </link>
  <link name="left_shoulder_yaw_link">
    <inertial>
      <origin xyz="0.010773 -0.002949 -0.072009" rpy="-0.23404932 0.035113349 1.5243037"/>
      <mass value="0.734"/>
      <inertia ixx="0.00106187" iyy="0.00103217" izz="0.000400661" ixy="0" ixz="0" iyz="0"/>
    </inertial>
    <visual>
      <origin xyz="0 0 0" rpy="0 0 0"/>
      <geometry>
        <mesh filename="package://g1_description/meshes/left_shoulder_yaw_link.STL"/>
      </geometry>
      <material name="mesh_mat">
        <color rgba="0.700 0.700 0.700 1.000"/>
      </material>
    </visual>
    <collision>
      <origin xyz="0 0 -0.05" rpy="0 0 0"/>
      <geometry>
        <cylinder radius="0.03" length="0.1"/>
      </geometry>
    </collision>
  </link>
  <link name="left_elbow_link">
    <inertial>
      <origin xyz="0.064956 0.004454 -0.010062" rpy="1.6830179 -0.072567008 1.1621208"/>
      <mass value="0.6"/>
      <inertia ixx="0.000443035" iyy="0.000421612" izz="0.000259353" ixy="0" ixz="0" iyz="0"/>
    </inertial>
    <visual>
      <origin xyz="0 0 0" rpy="0 0 0"/>
      <geometry>
        <mesh filename="package://g1_description/meshes/left_elbow_link.STL"/>
      </geometry>
      <material name="mesh_mat">
        <color rgba="0.700 0.700 0.700 1.000"/>
      </material>
    </visual>
    <collision>
      <origin xyz="0.12 0 0" rpy="0 1.5694152 0"/>
      <geometry>
        <cylinder radius="0.03" length="0.1"/>
      </geometry>
    </collision>
  </link>
  <link name="left_wrist_roll_link">
    <inertial>
      <origin xyz="0.0171394 0.000537591 4.8864e-07" rpy="1.5444407 -1.568901 -0.30349369"/>
      <mass value="0.085445"/>
      <inertia ixx="5.48211e-05" iyy="4.96646e-05" izz="3.57798e-05" ixy="0" ixz="0" iyz="0"/>
    </inertial>
    <visual>
      <origin xyz="0 0 0" rpy="0 0 0"/>
      <geometry>
        <mesh filename="package://g1_description/meshes/left_wrist_roll_link.STL"/>
      </geometry>
      <material name="mesh_mat">
        <color rgba="0.700 0.700 0.700 1.000"/>
      </material>
    </visual>
  </link>
  <link name="left_wrist_pitch_link">
    <inertial>
      <origin xyz="0.0229999 -0.00111685 -0.00111658" rpy="1.6364506 -0.78214147 1.5710821"/>
      <mass value="0.48405"/>
      <inertia ixx="0.000430353" iyy="0.000429873" izz="0.000164648" ixy="0" ixz="0" iyz="0"/>
    </inertial>
    <visual>
      <origin xyz="0 0 0" rpy="0 0 0"/>
      <geometry>
        <mesh filename="package://g1_description/meshes/left_wrist_pitch_link.STL"/>
      </geometry>
      <material name="mesh_mat">
        <color rgba="0.700 0.700 0.700 1.000"/>
      </material>
    </visual>
  </link>
  <link name="left_wrist_yaw_link">
    <inertial>
      <origin xyz="0.0220038 0.000494851 0.000538611" rpy="-0.36502042 -0.012764769 1.6090384"/>
      <mass value="0.0845765"/>
      <inertia ixx="5.97564e-05" iyy="5.09807e-05" izz="3.75684e-05" ixy="0" ixz="0" iyz="0"/>
    </inertial>
    <visual>
      <origin xyz="0 0 0" rpy="0 0 0"/>
      <geometry>
        <mesh filename="package://g1_description/meshes/left_wrist_yaw_link.STL"/>
      </geometry>
      <material name="mesh_mat">
        <color rgba="0.700 0.700 0.700 1.000"/>
      </material>
    </visual>
  </link>
  <link name="left_base_link">
    <inertial>
      <origin xyz="-0.00109123 0.00334947 0.0489856" rpy="0.20054468 0.07161473 1.5782904"/>
      <mass value="0.303576"/>
      <inertia ixx="0.000499703" iyy="0.000324117" izz="0.000231831" ixy="0" ixz="0" iyz="0"/>
    </inertial>
    <visual>
      <origin xyz="0 0 0" rpy="0 0 0"/>
      <geometry>
        <mesh filename="package://g1_description/meshes/right_base_link.STL"/>
      </geometry>
      <material name="mesh_mat">
        <color rgba="0.700 0.700 0.700 1.000"/>
      </material>
    </visual>
    <collision>
      <origin xyz="-0.031 -0.0045 0.096" rpy="1.5707963 -1.5707963 0"/>
      <geometry>
        <box size="0.012 0.012 0.012"/>
      </geometry>
    </collision>
    <collision>
      <origin xyz="-0.009 -0.0045 0.096" rpy="1.5707963 -1.5707963 0"/>
      <geometry>
        <box size="0.012 0.012 0.012"/>
      </geometry>
    </collision>
    <collision>
      <origin xyz="0.014 -0.0045 0.096" rpy="1.5707963 -1.5707963 0"/>
      <geometry>
        <box size="0.012 0.012 0.012"/>
      </geometry>
    </collision>
    <collision>
      <origin xyz="0.036 -0.0045 0.081" rpy="1.5707963 -1.5707963 0"/>
      <geometry>
        <box size="0.012 0.012 0.012"/>
      </geometry>
    </collision>
    <collision>
      <origin xyz="0.028 -0.0015 0.034" rpy="1.5707938 1.2740947 3.1415927"/>
      <geometry>
        <box size="0.058 0.02 0.046"/>
      </geometry>
    </collision>
    <collision>
      <origin xyz="0 0.007 0.07" rpy="1.5707963 -1.5707963 0"/>
      <geometry>
        <box size="0.032 0.088 0.03"/>
      </geometry>
    </collision>
    <collision>
      <origin xyz="-0.002 -0.014 0.0745" rpy="0 0.2620346 1.5690723"/>
      <geometry>
        <box size="0.0142 0.084 0.026"/>
      </geometry>
    </collision>
    <collision>
      <origin xyz="-0.002 -0.0015 0.052" rpy="1.5707963 -1.5707963 0"/>
      <geometry>
        <box size="0.024 0.084 0.046"/>
      </geometry>
    </collision>
    <collision>
      <origin xyz="0.003 -0.0015 0.022" rpy="1.5707963 -1.5707963 0"/>
      <geometry>
        <box size="0.044 0.04 0.046"/>
      </geometry>
    </collision>
    <collision>
      <origin xyz="-0.041 0.004 0.002" rpy="1.5707963 -1.5707963 0"/>
      <geometry>
        <box size="0.004 0.036 0.034"/>
      </geometry>
    </collision>
    <collision>
      <origin xyz="-0.047 0.02 0.022" rpy="1.5707963 -1.5707963 0"/>
      <geometry>
        <box size="0.044 0.056 0.004"/>
      </geometry>
    </collision>
  </link>
  <link name="left_index_f_link">
    <inertial>
      <origin xyz="0 0 0.0017" rpy="0 0 0"/>
      <mass value="0.000169697"/>
      <inertia ixx="1.29009e-09" iyy="1.29009e-09" izz="7.6801e-10" ixy="0" ixz="0" iyz="0"/>
    </inertial>
    <visual>
      <origin xyz="0 0 0" rpy="0 0 0"/>
      <geometry>
        <mesh filename="package://g1_description/meshes/right_index_f_link.STL"/>
      </geometry>
      <material name="mesh_mat">
        <color rgba="0.700 0.700 0.700 1.000"/>
      </material>
    </visual>
  </link>
  <link name="left_index_proximal_link">
    <inertial>
      <origin xyz="6.14568e-08 -0.00357858 0.0205176" rpy="-3.0658676e-06 0.050741612 -1.5708552"/>
      <mass value="0.00600337"/>
      <inertia ixx="8.89988e-07" iyy="8.65278e-07" izz="2.05352e-07" ixy="0" ixz="0" iyz="0"/>
    </inertial>
    <visual>
      <origin xyz="0 0 0" rpy="0 0 0"/>
      <geometry>
        <mesh filename="package://g1_description/meshes/right_index_proximal_link.STL"/>
      </geometry>
      <material name="mesh_mat">
        <color rgba="0.700 0.700 0.700 1.000"/>
      </material>
    </visual>
    <collision>
      <origin xyz="0 -0.003 0.019" rpy="0 0 0"/>
      <geometry>
        <box size="0.012 0.012 0.026"/>
      </geometry>
    </collision>
  </link>
  <link name="left_index_middle_link">
    <inertial>
      <origin xyz="-2.38785e-08 -0.00110516 0.00939619" rpy="1.859384e-05 -0.054304015 -1.570836"/>
      <mass value="0.0023759"/>
      <inertia ixx="1.62521e-07" iyy="1.35575e-07" izz="7.42871e-08" ixy="0" ixz="0" iyz="0"/>
    </inertial>
    <visual>
      <origin xyz="0 0 0" rpy="0 0 0"/>
      <geometry>
        <mesh filename="package://g1_description/meshes/right_index_middle_link.STL"/>
      </geometry>
      <material name="mesh_mat">
        <color rgba="0.700 0.700 0.700 1.000"/>
      </material>
    </visual>
    <collision>
      <origin xyz="0 -0.001 0.006" rpy="0 0 0"/>
      <geometry>
        <box size="0.012 0.01 0.02"/>
      </geometry>
    </collision>
  </link>
  <link name="left_index_distal_link">
    <inertial>
      <origin xyz="0.00184412 0.000358323 0.0107277" rpy="-0.19962294 -0.33092873 -1.531067"/>
      <mass value="0.00309312"/>
      <inertia ixx="1.89064e-07" iyy="1.75544e-07" izz="6.39413e-08" ixy="0" ixz="0" iyz="0"/>
    </inertial>
    <visual>
      <origin xyz="0 0 0" rpy="0 0 0"/>
      <geometry>
        <mesh filename="package://g1_description/meshes/right_index_distal_link.STL"/>
      </geometry>
      <material name="mesh_mat">
        <color rgba="0.700 0.700 0.700 1.000"/>
      </material>
    </visual>
    <collision>
      <origin xyz="0 -0.003 0.014" rpy="0 0 0"/>
      <geometry>
        <box size="0.01 0.01 0.02"/>
      </geometry>
    </collision>
  </link>
  <link name="left_index_tip_link">
    <inertial>
      <origin xyz="-2.37981e-08 -0.00705353 -0.0124434" rpy="0 0.28824931 1.5707977"/>
      <mass value="0.000390243"/>
      <inertia ixx="1.50776e-08" iyy="1.25259e-08" izz="7.70037e-09" ixy="0" ixz="0" iyz="0"/>
    </inertial>
    <visual>
      <origin xyz="0 0 0" rpy="0 0 0"/>
      <geometry>
        <mesh filename="package://g1_description/meshes/right_index_tip_link.STL"/>
      </geometry>
      <material name="mesh_mat">
        <color rgba="0.750 0.750 0.750 1.000"/>
      </material>
    </visual>
  </link>
  <link name="left_middle_f_link">
    <inertial>
      <origin xyz="0 0 0.0017" rpy="0 0 0"/>
      <mass value="0.000169697"/>
      <inertia ixx="1.29009e-09" iyy="1.29009e-09" izz="7.6801e-10" ixy="0" ixz="0" iyz="0"/>
    </inertial>
    <visual>
      <origin xyz="0 0 0" rpy="0 0 0"/>
      <geometry>
        <mesh filename="package://g1_description/meshes/right_middle_f_link.STL"/>
      </geometry>
      <material name="mesh_mat">
        <color rgba="0.700 0.700 0.700 1.000"/>
      </material>
    </visual>
  </link>
  <link name="left_middle_proximal_link">
    <inertial>
      <origin xyz="5.79907e-08 -0.00357858 0.0205176" rpy="-2.7087732e-06 0.05074147 -1.5708467"/>
      <mass value="0.00600338"/>
      <inertia ixx="8.89988e-07" iyy="8.65279e-07" izz="2.05352e-07" ixy="0" ixz="0" iyz="0"/>
    </inertial>
    <visual>
      <origin xyz="0 0 0" rpy="0 0 0"/>
      <geometry>
        <mesh filename="package://g1_description/meshes/right_middle_proximal_link.STL"/>
      </geometry>
      <material name="mesh_mat">
        <color rgba="0.700 0.700 0.700 1.000"/>
      </material>
    </visual>
    <collision>
      <origin xyz="0 -0.003 0.019" rpy="0 0 0"/>
      <geometry>
        <box size="0.012 0.012 0.026"/>
      </geometry>
    </collision>
  </link>
  <link name="left_middle_middle_link">
    <inertial>
      <origin xyz="-9.42153e-09 -0.00110516 0.00939618" rpy="2.0228078e-05 -0.054303023 -1.5708389"/>
      <mass value="0.0023759"/>
      <inertia ixx="1.62521e-07" iyy="1.35575e-07" izz="7.42872e-08" ixy="0" ixz="0" iyz="0"/>
    </inertial>
    <visual>
      <origin xyz="0 0 0" rpy="0 0 0"/>
      <geometry>
        <mesh filename="package://g1_description/meshes/right_middle_middle_link.STL"/>
      </geometry>
      <material name="mesh_mat">
        <color rgba="0.700 0.700 0.700 1.000"/>
      </material>
    </visual>
    <collision>
      <origin xyz="0 -0.001 0.006" rpy="0 0 0"/>
      <geometry>
        <box size="0.012 0.01 0.02"/>
      </geometry>
    </collision>
  </link>
  <link name="left_middle_distal_link">
    <inertial>
      <origin xyz="0.00184407 0.000358307 0.0107282" rpy="-0.19960884 -0.33092298 -1.5311022"/>
      <mass value="0.00309312"/>
      <inertia ixx="1.89075e-07" iyy="1.75556e-07" izz="6.39407e-08" ixy="0" ixz="0" iyz="0"/>
    </inertial>
    <visual>
      <origin xyz="0 0 0" rpy="0 0 0"/>
      <geometry>
        <mesh filename="package://g1_description/meshes/right_middle_distal_link.STL"/>
      </geometry>
      <material name="mesh_mat">
        <color rgba="0.700 0.700 0.700 1.000"/>
      </material>
    </visual>
    <collision>
      <origin xyz="0 -0.003 0.014" rpy="0 0 0"/>
      <geometry>
        <box size="0.01 0.01 0.02"/>
      </geometry>
    </collision>
  </link>
  <link name="left_middle_tip_link">
    <inertial>
      <origin xyz="7.96462e-08 -0.00705328 -0.0124433" rpy="0 0.28829184 1.5707953"/>
      <mass value="0.000390269"/>
      <inertia ixx="1.50781e-08" iyy="1.25267e-08" izz="7.70079e-09" ixy="0" ixz="0" iyz="0"/>
    </inertial>
    <visual>
      <origin xyz="0 0 0" rpy="0 0 0"/>
      <geometry>
        <mesh filename="package://g1_description/meshes/right_middle_tip_link.STL"/>
      </geometry>
      <material name="mesh_mat">
        <color rgba="0.750 0.750 0.750 1.000"/>
      </material>
    </visual>
  </link>
  <link name="left_ring_f_link">
    <inertial>
      <origin xyz="0 0 0.0017" rpy="0 0 0"/>
      <mass value="0.000169697"/>
      <inertia ixx="1.29009e-09" iyy="1.29009e-09" izz="7.6801e-10" ixy="0" ixz="0" iyz="0"/>
    </inertial>
    <visual>
      <origin xyz="0 0 0" rpy="0 0 0"/>
      <geometry>
        <mesh filename="package://g1_description/meshes/right_ring_f_link.STL"/>
      </geometry>
      <material name="mesh_mat">
        <color rgba="0.700 0.700 0.700 1.000"/>
      </material>
    </visual>
  </link>
  <link name="left_ring_proximal_link">
    <inertial>
      <origin xyz="4.27735e-08 -0.00357857 0.0205176" rpy="0 0.050742603 -1.5707957"/>
      <mass value="0.00600337"/>
      <inertia ixx="8.89987e-07" iyy="8.65277e-07" izz="2.05351e-07" ixy="0" ixz="0" iyz="0"/>
    </inertial>
    <visual>
      <origin xyz="0 0 0" rpy="0 0 0"/>
      <geometry>
        <mesh filename="package://g1_description/meshes/right_ring_proximal_link.STL"/>
      </geometry>
      <material name="mesh_mat">
        <color rgba="0.700 0.700 0.700 1.000"/>
      </material>
    </visual>
    <collision>
      <origin xyz="0 -0.003 0.019" rpy="0 0 0"/>
      <geometry>
        <box size="0.012 0.012 0.026"/>
      </geometry>
    </collision>
  </link>
  <link name="left_ring_middle_link">
    <inertial>
      <origin xyz="-5.2917e-09 -0.00110519 0.0093962" rpy="1.798039e-05 -0.054300154 -1.5707963"/>
      <mass value="0.00237591"/>
      <inertia ixx="1.62521e-07" iyy="1.35575e-07" izz="7.42877e-08" ixy="0" ixz="0" iyz="0"/>
    </inertial>
    <visual>
      <origin xyz="0 0 0" rpy="0 0 0"/>
      <geometry>
        <mesh filename="package://g1_description/meshes/right_ring_middle_link.STL"/>
      </geometry>
      <material name="mesh_mat">
        <color rgba="0.700 0.700 0.700 1.000"/>
      </material>
    </visual>
    <collision>
      <origin xyz="0 -0.001 0.006" rpy="0 0 0"/>
      <geometry>
        <box size="0.012 0.01 0.02"/>
      </geometry>
    </collision>
  </link>
  <link name="left_ring_distal_link">
    <inertial>
      <origin xyz="0.00184407 0.000358289 0.0107282" rpy="-0.19960808 -0.33092402 -1.5310994"/>
      <mass value="0.00309314"/>
      <inertia ixx="1.89076e-07" iyy="1.75558e-07" izz="6.39409e-08" ixy="0" ixz="0" iyz="0"/>
    </inertial>
    <visual>
      <origin xyz="0 0 0" rpy="0 0 0"/>
      <geometry>
        <mesh filename="package://g1_description/meshes/right_ring_distal_link.STL"/>
      </geometry>
      <material name="mesh_mat">
        <color rgba="0.700 0.700 0.700 1.000"/>
      </material>
    </visual>
    <collision>
      <origin xyz="0 -0.003 0.014" rpy="0 0 0"/>
      <geometry>
        <box size="0.01 0.01 0.02"/>
      </geometry>
    </collision>
  </link>
  <link name="left_ring_tip_link">
    <inertial>
      <origin xyz="5.22174e-09 -0.00705336 -0.0124436" rpy="0 0.28826641 1.5707974"/>
      <mass value="0.000390294"/>
      <inertia ixx="1.50784e-08" iyy="1.2527e-08" izz="7.70085e-09" ixy="0" ixz="0" iyz="0"/>
    </inertial>
    <visual>
      <origin xyz="0 0 0" rpy="0 0 0"/>
      <geometry>
        <mesh filename="package://g1_description/meshes/right_ring_tip_link.STL"/>
      </geometry>
      <material name="mesh_mat">
        <color rgba="0.750 0.750 0.750 1.000"/>
      </material>
    </visual>
  </link>
  <link name="left_pinky_f_link">
    <inertial>
      <origin xyz="0 0 0.0017" rpy="0 0 0"/>
      <mass value="0.000169697"/>
      <inertia ixx="1.29009e-09" iyy="1.29009e-09" izz="7.6801e-10" ixy="0" ixz="0" iyz="0"/>
    </inertial>
    <visual>
      <origin xyz="0 0 0" rpy="0 0 0"/>
      <geometry>
        <mesh filename="package://g1_description/meshes/right_pinky_f_link.STL"/>
      </geometry>
      <material name="mesh_mat">
        <color rgba="0.700 0.700 0.700 1.000"/>
      </material>
    </visual>
  </link>
  <link name="left_pinky_proximal_link">
    <inertial>
      <origin xyz="4.24866e-08 -0.00357857 0.0205176" rpy="0 0.050742603 -1.5707957"/>
      <mass value="0.00600337"/>
      <inertia ixx="8.89987e-07" iyy="8.65277e-07" izz="2.05351e-07" ixy="0" ixz="0" iyz="0"/>
    </inertial>
    <visual>
      <origin xyz="0 0 0" rpy="0 0 0"/>
      <geometry>
        <mesh filename="package://g1_description/meshes/right_pinky_proximal_link.STL"/>
      </geometry>
      <material name="mesh_mat">
        <color rgba="0.700 0.700 0.700 1.000"/>
      </material>
    </visual>
    <collision>
      <origin xyz="0 -0.003 0.019" rpy="0 0 0"/>
      <geometry>
        <box size="0.012 0.012 0.026"/>
      </geometry>
    </collision>
  </link>
  <link name="left_pinky_middle_link">
    <inertial>
      <origin xyz="-1.1729e-08 -0.00110519 0.0093962" rpy="1.7272501e-05 -0.054300862 -1.5707963"/>
      <mass value="0.00237591"/>
      <inertia ixx="1.6252e-07" iyy="1.35575e-07" izz="7.42876e-08" ixy="0" ixz="0" iyz="0"/>
    </inertial>
    <visual>
      <origin xyz="0 0 0" rpy="0 0 0"/>
      <geometry>
        <mesh filename="package://g1_description/meshes/right_pinky_middle_link.STL"/>
      </geometry>
      <material name="mesh_mat">
        <color rgba="0.700 0.700 0.700 1.000"/>
      </material>
    </visual>
    <collision>
      <origin xyz="0 -0.001 0.006" rpy="0 0 0"/>
      <geometry>
        <box size="0.012 0.01 0.02"/>
      </geometry>
    </collision>
  </link>
  <link name="left_pinky_distal_link">
    <inertial>
      <origin xyz="0.00184407 0.000358264 0.0107282" rpy="-0.19960648 -0.33092209 -1.5311051"/>
      <mass value="0.00309314"/>
      <inertia ixx="1.89076e-07" iyy="1.75557e-07" izz="6.3941e-08" ixy="0" ixz="0" iyz="0"/>
    </inertial>
    <visual>
      <origin xyz="0 0 0" rpy="0 0 0"/>
      <geometry>
        <mesh filename="package://g1_description/meshes/right_pinky_distal_link.STL"/>
      </geometry>
      <material name="mesh_mat">
        <color rgba="0.700 0.700 0.700 1.000"/>
      </material>
    </visual>
    <collision>
      <origin xyz="0 -0.003 0.014" rpy="0 0 0"/>
      <geometry>
        <box size="0.01 0.01 0.02"/>
      </geometry>
    </collision>
  </link>
  <link name="left_pinky_tip_link">
    <inertial>
      <origin xyz="-2.46097e-08 -0.00705336 -0.0124437" rpy="0 0.28826641 1.5707974"/>
      <mass value="0.000390295"/>
      <inertia ixx="1.50784e-08" iyy="1.2527e-08" izz="7.70086e-09" ixy="0" ixz="0" iyz="0"/>
    </inertial>
    <visual>
      <origin xyz="0 0 0" rpy="0 0 0"/>
      <geometry>
        <mesh filename="package://g1_description/meshes/right_pinky_tip_link.STL"/>
      </geometry>
      <material name="mesh_mat">
        <color rgba="0.750 0.750 0.750 1.000"/>
      </material>
    </visual>
  </link>
  <link name="left_t_link">
    <inertial>
      <origin xyz="0.000792597 0.00920489 0.00837042" rpy="-0.47620725 0.078572407 -0.15665522"/>
      <mass value="0.00893482"/>
      <inertia ixx="1.11708e-06" iyy="8.42419e-07" izz="4.36164e-07" ixy="0" ixz="0" iyz="0"/>
    </inertial>
    <visual>
      <origin xyz="0 0 0" rpy="0 0 0"/>
      <geometry>
        <mesh filename="package://g1_description/meshes/right_t_link.STL"/>
      </geometry>
      <material name="mesh_mat">
        <color rgba="0.700 0.700 0.700 1.000"/>
      </material>
    </visual>
    <collision>
      <origin xyz="0.01 0.015 0.005" rpy="0 0 0"/>
      <geometry>
        <box size="0.03 0.016 0.016"/>
      </geometry>
    </collision>
  </link>
  <link name="left_thumb_mcp_link">
    <inertial>
      <origin xyz="3.98621e-09 -0.0014303 0.0147562" rpy="-1.4315147e-05 0.058078062 -1.5707835"/>
      <mass value="0.0102694"/>
      <inertia ixx="1.58158e-06" iyy="1.39018e-06" izz="6.7267e-07" ixy="0" ixz="0" iyz="0"/>
    </inertial>
    <visual>
      <origin xyz="0 0 0" rpy="0 0 0"/>
      <geometry>
        <mesh filename="package://g1_description/meshes/right_thumb_mcp_link.STL"/>
      </geometry>
      <material name="mesh_mat">
        <color rgba="0.700 0.700 0.700 1.000"/>
      </material>
    </visual>
    <collision>
      <origin xyz="0 0 0.014" rpy="0 0 0"/>
      <geometry>
        <box size="0.016 0.02 0.032"/>
      </geometry>
    </collision>
  </link>
  <link name="left_thumb_proximal_link">
    <inertial>
      <origin xyz="9.60413e-08 -0.00147723 0.0133935" rpy="2.1776953e-05 -0.030493743 -1.5707865"/>
      <mass value="0.00574573"/>
      <inertia ixx="6.77924e-07" iyy="5.00351e-07" izz="3.51862e-07" ixy="0" ixz="0" iyz="0"/>
    </inertial>
    <visual>
      <origin xyz="0 0 0" rpy="0 0 0"/>
      <geometry>
        <mesh filename="package://g1_description/meshes/right_thumb_proximal_link.STL"/>
      </geometry>
      <material name="mesh_mat">
        <color rgba="0.700 0.700 0.700 1.000"/>
      </material>
    </visual>
    <collision>
      <origin xyz="0 -0.002 0.012" rpy="0 0 0"/>
      <geometry>
        <box size="0.016 0.012 0.024"/>
      </geometry>
    </collision>
  </link>
  <link name="left_thumb_distal_link">
    <inertial>
      <origin xyz="0.00113926 -0.00130909 0.0133464" rpy="-0.12885968 -0.27095325 -1.5547385"/>
      <mass value="0.00692863"/>
      <inertia ixx="6.65186e-07" iyy="5.66522e-07" izz="2.78338e-07" ixy="0" ixz="0" iyz="0"/>
    </inertial>
    <visual>
      <origin xyz="0 0 0" rpy="0 0 0"/>
      <geometry>
        <mesh filename="package://g1_description/meshes/right_thumb_distal_link.STL"/>
      </geometry>
      <material name="mesh_mat">
        <color rgba="0.700 0.700 0.700 1.000"/>
      </material>
    </visual>
    <collision>
      <origin xyz="0 -0.002 0.015" rpy="0 0 0"/>
      <geometry>
        <box size="0.016 0.012 0.024"/>
      </geometry>
    </collision>
  </link>
  <link name="left_thumb_tip_link">
    <inertial>
      <origin xyz="-2.2383e-07 -0.010203 -0.013939" rpy="-0.00041469501 0.3161801 1.5705756"/>
      <mass value="0.00086967"/>
      <inertia ixx="6.48507e-08" iyy="5.0257e-08" izz="3.56243e-08" ixy="0" ixz="0" iyz="0"/>
    </inertial>
    <visual>
      <origin xyz="0 0 0" rpy="0 0 0"/>
      <geometry>
        <mesh filename="package://g1_description/meshes/right_thumb_tip_link.STL"/>
      </geometry>
      <material name="mesh_mat">
        <color rgba="0.750 0.750 0.750 1.000"/>
      </material>
    </visual>
  </link>
  <link name="right_shoulder_pitch_link">
    <inertial>
      <origin xyz="0 -0.035892 -0.011628" rpy="-0.49834897 0.46079175 1.40952"/>
      <mass value="0.718"/>
      <inertia ixx="0.000465864" iyy="0.000432842" izz="0.000406394" ixy="0" ixz="0" iyz="0"/>
    </inertial>
    <visual>
      <origin xyz="0 0 0" rpy="0 0 0"/>
      <geometry>
        <mesh filename="package://g1_description/meshes/right_shoulder_pitch_link.STL"/>
      </geometry>
      <material name="mesh_mat">
        <color rgba="0.700 0.700 0.700 1.000"/>
      </material>
    </visual>
  </link>
  <link name="right_shoulder_roll_link">
    <inertial>
      <origin xyz="-0.000227 -0.00727 -0.063243" rpy="-0.037659009 -0.01800455 1.5550832"/>
      <mass value="0.643"/>
      <inertia ixx="0.000691311" iyy="0.000618011" izz="0.000388977" ixy="0" ixz="0" iyz="0"/>
    </inertial>
    <visual>
      <origin xyz="0 0 0" rpy="0 0 0"/>
      <geometry>
        <mesh filename="package://g1_description/meshes/right_shoulder_roll_link.STL"/>
      </geometry>
      <material name="mesh_mat">
        <color rgba="0.700 0.700 0.700 1.000"/>
      </material>
    </visual>
    <collision>
      <origin xyz="-0.004 -0.006 -0.053" rpy="0 0 0"/>
      <geometry>
        <cylinder radius="0.03" length="0.03"/>
      </geometry>
    </collision>
  </link>
  <link name="right_shoulder_yaw_link">
    <inertial>
      <origin xyz="0.010773 0.002949 -0.072009" rpy="-0.23404932 -0.035113349 1.6172906"/>
      <mass value="0.734"/>
      <inertia ixx="0.00106187" iyy="0.00103217" izz="0.000400661" ixy="0" ixz="0" iyz="0"/>
    </inertial>
    <visual>
      <origin xyz="0 0 0" rpy="0 0 0"/>
      <geometry>
        <mesh filename="package://g1_description/meshes/right_shoulder_yaw_link.STL"/>
      </geometry>
      <material name="mesh_mat">
        <color rgba="0.700 0.700 0.700 1.000"/>
      </material>
    </visual>
    <collision>
      <origin xyz="0 0 -0.05" rpy="0 0 0"/>
      <geometry>
        <cylinder radius="0.03" length="0.1"/>
      </geometry>
    </collision>
  </link>
  <link name="right_elbow_link">
    <inertial>
      <origin xyz="0.064956 -0.004454 -0.010062" rpy="1.6830179 0.072567008 1.9794703"/>
      <mass value="0.6"/>
      <inertia ixx="0.000443035" iyy="0.000421612" izz="0.000259353" ixy="0" ixz="0" iyz="0"/>
    </inertial>
    <visual>
      <origin xyz="0 0 0" rpy="0 0 0"/>
      <geometry>
        <mesh filename="package://g1_description/meshes/right_elbow_link.STL"/>
      </geometry>
      <material name="mesh_mat">
        <color rgba="0.700 0.700 0.700 1.000"/>
      </material>
    </visual>
    <collision>
      <origin xyz="0.12 0 0" rpy="0 1.5694152 0"/>
      <geometry>
        <cylinder radius="0.03" length="0.1"/>
      </geometry>
    </collision>
  </link>
  <link name="right_wrist_roll_link">
    <inertial>
      <origin xyz="0.0171394 -0.000537591 4.8864e-07" rpy="1.5946278 -1.568901 0.30349369"/>
      <mass value="0.085445"/>
      <inertia ixx="5.48211e-05" iyy="4.96646e-05" izz="3.57798e-05" ixy="0" ixz="0" iyz="0"/>
    </inertial>
    <visual>
      <origin xyz="0 0 0" rpy="0 0 0"/>
      <geometry>
        <mesh filename="package://g1_description/meshes/right_wrist_roll_link.STL"/>
      </geometry>
      <material name="mesh_mat">
        <color rgba="0.700 0.700 0.700 1.000"/>
      </material>
    </visual>
  </link>
  <link name="right_wrist_pitch_link">
    <inertial>
      <origin xyz="0.0229999 0.00111685 -0.00111658" rpy="1.6364506 0.78214147 1.5705145"/>
      <mass value="0.48405"/>
      <inertia ixx="0.000430353" iyy="0.000429873" izz="0.000164648" ixy="0" ixz="0" iyz="0"/>
    </inertial>
    <visual>
      <origin xyz="0 0 0" rpy="0 0 0"/>
      <geometry>
        <mesh filename="package://g1_description/meshes/right_wrist_pitch_link.STL"/>
      </geometry>
      <material name="mesh_mat">
        <color rgba="0.700 0.700 0.700 1.000"/>
      </material>
    </visual>
  </link>
  <link name="right_wrist_yaw_link">
    <inertial>
      <origin xyz="0.0220038 -0.000494851 0.000538611" rpy="-0.36502042 0.012764769 1.5325544"/>
      <mass value="0.0845765"/>
      <inertia ixx="5.97564e-05" iyy="5.09807e-05" izz="3.75684e-05" ixy="0" ixz="0" iyz="0"/>
    </inertial>
    <visual>
      <origin xyz="0 0 0" rpy="0 0 0"/>
      <geometry>
        <mesh filename="package://g1_description/meshes/right_wrist_yaw_link.STL"/>
      </geometry>
      <material name="mesh_mat">
        <color rgba="0.700 0.700 0.700 1.000"/>
      </material>
    </visual>
  </link>
  <link name="right_base_link">
    <inertial>
      <origin xyz="0.00109123 0.00334947 0.0489856" rpy="-0.20054468 0.07161473 1.5633022"/>
      <mass value="0.303576"/>
      <inertia ixx="0.000499703" iyy="0.000324117" izz="0.000231831" ixy="0" ixz="0" iyz="0"/>
    </inertial>
    <visual>
      <origin xyz="0 0 0" rpy="0 0 0"/>
      <geometry>
        <mesh filename="package://g1_description/meshes/right_base_link.STL"/>
      </geometry>
      <material name="mesh_mat">
        <color rgba="0.700 0.700 0.700 1.000"/>
      </material>
    </visual>
    <collision>
      <origin xyz="0.031 -0.0045 0.096" rpy="1.5707963 1.5707963 0"/>
      <geometry>
        <box size="0.012 0.012 0.012"/>
      </geometry>
    </collision>
    <collision>
      <origin xyz="0.009 -0.0045 0.096" rpy="1.5707963 1.5707963 0"/>
      <geometry>
        <box size="0.012 0.012 0.012"/>
      </geometry>
    </collision>
    <collision>
      <origin xyz="-0.014 -0.0045 0.096" rpy="1.5707963 1.5707963 0"/>
      <geometry>
        <box size="0.012 0.012 0.012"/>
      </geometry>
    </collision>
    <collision>
      <origin xyz="-0.036 -0.0045 0.081" rpy="1.5707963 1.5707963 0"/>
      <geometry>
        <box size="0.012 0.012 0.012"/>
      </geometry>
    </collision>
    <collision>
      <origin xyz="-0.028 -0.0015 0.034" rpy="1.5707938 -1.2740947 3.1415927"/>
      <geometry>
        <box size="0.058 0.02 0.046"/>
      </geometry>
    </collision>
    <collision>
      <origin xyz="0 0.007 0.07" rpy="1.5707963 1.5707963 0"/>
      <geometry>
        <box size="0.032 0.088 0.03"/>
      </geometry>
    </collision>
    <collision>
      <origin xyz="0.002 -0.014 0.0745" rpy="0 -0.2620346 -1.5690723"/>
      <geometry>
        <box size="0.0142 0.084 0.026"/>
      </geometry>
    </collision>
    <collision>
      <origin xyz="0.002 -0.0015 0.052" rpy="1.5707963 1.5707963 0"/>
      <geometry>
        <box size="0.024 0.084 0.046"/>
      </geometry>
    </collision>
    <collision>
      <origin xyz="-0.003 -0.0015 0.022" rpy="1.5707963 1.5707963 0"/>
      <geometry>
        <box size="0.044 0.04 0.046"/>
      </geometry>
    </collision>
    <collision>
      <origin xyz="0.041 0.004 0.002" rpy="1.5707963 1.5707963 0"/>
      <geometry>
        <box size="0.004 0.036 0.034"/>
      </geometry>
    </collision>
    <collision>
      <origin xyz="0.047 0.02 0.022" rpy="1.5707963 1.5707963 0"/>
      <geometry>
        <box size="0.044 0.056 0.004"/>
      </geometry>
    </collision>
  </link>
  <link name="right_index_f_link">
    <inertial>
      <origin xyz="0 0 0.0017" rpy="0 0 0"/>
      <mass value="0.000169697"/>
      <inertia ixx="1.29009e-09" iyy="1.29009e-09" izz="7.6801e-10" ixy="0" ixz="0" iyz="0"/>
    </inertial>
  </link>
  <link name="right_index_proximal_link">
    <inertial>
      <origin xyz="-6.14568e-08 -0.00357858 0.0205176" rpy="-3.0658676e-06 -0.050741612 1.5708552"/>
      <mass value="0.00600337"/>
      <inertia ixx="8.89988e-07" iyy="8.65278e-07" izz="2.05352e-07" ixy="0" ixz="0" iyz="0"/>
    </inertial>
    <visual>
      <origin xyz="0 0 0" rpy="0 0 0"/>
      <geometry>
        <mesh filename="package://g1_description/meshes/right_index_proximal_link.STL"/>
      </geometry>
      <material name="mesh_mat">
        <color rgba="0.700 0.700 0.700 1.000"/>
      </material>
    </visual>
    <collision>
      <origin xyz="0 -0.003 0.019" rpy="0 0 0"/>
      <geometry>
        <box size="0.012 0.012 0.026"/>
      </geometry>
    </collision>
  </link>
  <link name="right_index_middle_link">
    <inertial>
      <origin xyz="2.38785e-08 -0.00110516 0.00939619" rpy="1.859384e-05 0.054304015 1.570836"/>
      <mass value="0.0023759"/>
      <inertia ixx="1.62521e-07" iyy="1.35575e-07" izz="7.42871e-08" ixy="0" ixz="0" iyz="0"/>
    </inertial>
    <visual>
      <origin xyz="0 0 0" rpy="0 0 0"/>
      <geometry>
        <mesh filename="package://g1_description/meshes/right_index_middle_link.STL"/>
      </geometry>
      <material name="mesh_mat">
        <color rgba="0.700 0.700 0.700 1.000"/>
      </material>
    </visual>
    <collision>
      <origin xyz="0 -0.001 0.006" rpy="0 0 0"/>
      <geometry>
        <box size="0.012 0.01 0.02"/>
      </geometry>
    </collision>
  </link>
  <link name="right_index_distal_link">
    <inertial>
      <origin xyz="-0.00184412 0.000358323 0.0107277" rpy="-0.19962294 0.33092873 1.531067"/>
      <mass value="0.00309312"/>
      <inertia ixx="1.89064e-07" iyy="1.75544e-07" izz="6.39413e-08" ixy="0" ixz="0" iyz="0"/>
    </inertial>
    <visual>
      <origin xyz="0 0 0" rpy="0 0 0"/>
      <geometry>
        <mesh filename="package://g1_description/meshes/right_index_distal_link.STL"/>
      </geometry>
      <material name="mesh_mat">
        <color rgba="0.700 0.700 0.700 1.000"/>
      </material>
    </visual>
    <collision>
      <origin xyz="0 -0.003 0.014" rpy="0 0 0"/>
      <geometry>
        <box size="0.01 0.01 0.02"/>
      </geometry>
    </collision>
  </link>
  <link name="right_index_tip_link">
    <inertial>
      <origin xyz="2.37981e-08 -0.00705353 -0.0124434" rpy="0 0.28824931 1.5707977"/>
      <mass value="0.000390243"/>
      <inertia ixx="1.50776e-08" iyy="1.25259e-08" izz="7.70037e-09" ixy="0" ixz="0" iyz="0"/>
    </inertial>
    <visual>
      <origin xyz="0 0 0" rpy="0 0 0"/>
      <geometry>
        <mesh filename="package://g1_description/meshes/right_index_tip_link.STL"/>
      </geometry>
      <material name="mesh_mat">
        <color rgba="0.750 0.750 0.750 1.000"/>
      </material>
    </visual>
  </link>
  <link name="right_middle_f_link">
    <inertial>
      <origin xyz="0 0 0.0017" rpy="0 0 0"/>
      <mass value="0.000169697"/>
      <inertia ixx="1.29009e-09" iyy="1.29009e-09" izz="7.6801e-10" ixy="0" ixz="0" iyz="0"/>
    </inertial>
  </link>
  <link name="right_middle_proximal_link">
    <inertial>
      <origin xyz="-5.79907e-08 -0.00357858 0.0205176" rpy="-2.7087732e-06 -0.05074147 1.5708467"/>
      <mass value="0.00600338"/>
      <inertia ixx="8.89988e-07" iyy="8.65279e-07" izz="2.05352e-07" ixy="0" ixz="0" iyz="0"/>
    </inertial>
    <visual>
      <origin xyz="0 0 0" rpy="0 0 0"/>
      <geometry>
        <mesh filename="package://g1_description/meshes/right_middle_proximal_link.STL"/>
      </geometry>
      <material name="mesh_mat">
        <color rgba="0.700 0.700 0.700 1.000"/>
      </material>
    </visual>
    <collision>
      <origin xyz="0 -0.003 0.019" rpy="0 0 0"/>
      <geometry>
        <box size="0.012 0.012 0.026"/>
      </geometry>
    </collision>
  </link>
  <link name="right_middle_middle_link">
    <inertial>
      <origin xyz="9.42153e-09 -0.00110516 0.00939618" rpy="2.0228078e-05 0.054303023 1.5708389"/>
      <mass value="0.0023759"/>
      <inertia ixx="1.62521e-07" iyy="1.35575e-07" izz="7.42872e-08" ixy="0" ixz="0" iyz="0"/>
    </inertial>
    <visual>
      <origin xyz="0 0 0" rpy="0 0 0"/>
      <geometry>
        <mesh filename="package://g1_description/meshes/right_middle_middle_link.STL"/>
      </geometry>
      <material name="mesh_mat">
        <color rgba="0.700 0.700 0.700 1.000"/>
      </material>
    </visual>
    <collision>
      <origin xyz="0 -0.001 0.006" rpy="0 0 0"/>
      <geometry>
        <box size="0.012 0.01 0.02"/>
      </geometry>
    </collision>
  </link>
  <link name="right_middle_distal_link">
    <inertial>
      <origin xyz="-0.00184407 0.000358307 0.0107282" rpy="-0.19960884 0.33092298 1.5311022"/>
      <mass value="0.00309312"/>
      <inertia ixx="1.89075e-07" iyy="1.75556e-07" izz="6.39407e-08" ixy="0" ixz="0" iyz="0"/>
    </inertial>
    <visual>
      <origin xyz="0 0 0" rpy="0 0 0"/>
      <geometry>
        <mesh filename="package://g1_description/meshes/right_middle_distal_link.STL"/>
      </geometry>
      <material name="mesh_mat">
        <color rgba="0.700 0.700 0.700 1.000"/>
      </material>
    </visual>
    <collision>
      <origin xyz="0 -0.003 0.014" rpy="0 0 0"/>
      <geometry>
        <box size="0.01 0.01 0.02"/>
      </geometry>
    </collision>
  </link>
  <link name="right_middle_tip_link">
    <inertial>
      <origin xyz="-7.96462e-08 -0.00705328 -0.0124433" rpy="0 0.28829184 1.5707953"/>
      <mass value="0.000390269"/>
      <inertia ixx="1.50781e-08" iyy="1.25267e-08" izz="7.70079e-09" ixy="0" ixz="0" iyz="0"/>
    </inertial>
    <visual>
      <origin xyz="0 0 0" rpy="0 0 0"/>
      <geometry>
        <mesh filename="package://g1_description/meshes/right_middle_tip_link.STL"/>
      </geometry>
      <material name="mesh_mat">
        <color rgba="0.750 0.750 0.750 1.000"/>
      </material>
    </visual>
  </link>
  <link name="right_ring_f_link">
    <inertial>
      <origin xyz="0 0 0.0017" rpy="0 0 0"/>
      <mass value="0.000169697"/>
      <inertia ixx="1.29009e-09" iyy="1.29009e-09" izz="7.6801e-10" ixy="0" ixz="0" iyz="0"/>
    </inertial>
  </link>
  <link name="right_ring_proximal_link">
    <inertial>
      <origin xyz="-4.27735e-08 -0.00357857 0.0205176" rpy="0 -0.050742603 1.5707957"/>
      <mass value="0.00600337"/>
      <inertia ixx="8.89987e-07" iyy="8.65277e-07" izz="2.05351e-07" ixy="0" ixz="0" iyz="0"/>
    </inertial>
    <visual>
      <origin xyz="0 0 0" rpy="0 0 0"/>
      <geometry>
        <mesh filename="package://g1_description/meshes/right_ring_proximal_link.STL"/>
      </geometry>
      <material name="mesh_mat">
        <color rgba="0.700 0.700 0.700 1.000"/>
      </material>
    </visual>
    <collision>
      <origin xyz="0 -0.003 0.019" rpy="0 0 0"/>
      <geometry>
        <box size="0.012 0.012 0.026"/>
      </geometry>
    </collision>
  </link>
  <link name="right_ring_middle_link">
    <inertial>
      <origin xyz="5.2917e-09 -0.00110519 0.0093962" rpy="1.798039e-05 0.054300154 1.5707963"/>
      <mass value="0.00237591"/>
      <inertia ixx="1.62521e-07" iyy="1.35575e-07" izz="7.42877e-08" ixy="0" ixz="0" iyz="0"/>
    </inertial>
    <visual>
      <origin xyz="0 0 0" rpy="0 0 0"/>
      <geometry>
        <mesh filename="package://g1_description/meshes/right_ring_middle_link.STL"/>
      </geometry>
      <material name="mesh_mat">
        <color rgba="0.700 0.700 0.700 1.000"/>
      </material>
    </visual>
    <collision>
      <origin xyz="0 -0.001 0.006" rpy="0 0 0"/>
      <geometry>
        <box size="0.012 0.01 0.02"/>
      </geometry>
    </collision>
  </link>
  <link name="right_ring_distal_link">
    <inertial>
      <origin xyz="-0.00184407 0.000358289 0.0107282" rpy="-0.19960808 0.33092402 1.5310994"/>
      <mass value="0.00309314"/>
      <inertia ixx="1.89076e-07" iyy="1.75558e-07" izz="6.39409e-08" ixy="0" ixz="0" iyz="0"/>
    </inertial>
    <visual>
      <origin xyz="0 0 0" rpy="0 0 0"/>
      <geometry>
        <mesh filename="package://g1_description/meshes/right_ring_distal_link.STL"/>
      </geometry>
      <material name="mesh_mat">
        <color rgba="0.700 0.700 0.700 1.000"/>
      </material>
    </visual>
    <collision>
      <origin xyz="0 -0.003 0.014" rpy="0 0 0"/>
      <geometry>
        <box size="0.01 0.01 0.02"/>
      </geometry>
    </collision>
  </link>
  <link name="right_ring_tip_link">
    <inertial>
      <origin xyz="-5.22174e-09 -0.00705336 -0.0124436" rpy="0 0.28826641 1.5707974"/>
      <mass value="0.000390294"/>
      <inertia ixx="1.50784e-08" iyy="1.2527e-08" izz="7.70085e-09" ixy="0" ixz="0" iyz="0"/>
    </inertial>
    <visual>
      <origin xyz="0 0 0" rpy="0 0 0"/>
      <geometry>
        <mesh filename="package://g1_description/meshes/right_ring_tip_link.STL"/>
      </geometry>
      <material name="mesh_mat">
        <color rgba="0.750 0.750 0.750 1.000"/>
      </material>
    </visual>
  </link>
  <link name="right_pinky_f_link">
    <inertial>
      <origin xyz="0 0 0.0017" rpy="0 0 0"/>
      <mass value="0.000169697"/>
      <inertia ixx="1.29009e-09" iyy="1.29009e-09" izz="7.6801e-10" ixy="0" ixz="0" iyz="0"/>
    </inertial>
  </link>
  <link name="right_pinky_proximal_link">
    <inertial>
      <origin xyz="-4.24866e-08 -0.00357857 0.0205176" rpy="0 -0.050742603 1.5707957"/>
      <mass value="0.00600337"/>
      <inertia ixx="8.89987e-07" iyy="8.65277e-07" izz="2.05351e-07" ixy="0" ixz="0" iyz="0"/>
    </inertial>
    <visual>
      <origin xyz="0 0 0" rpy="0 0 0"/>
      <geometry>
        <mesh filename="package://g1_description/meshes/right_pinky_proximal_link.STL"/>
      </geometry>
      <material name="mesh_mat">
        <color rgba="0.700 0.700 0.700 1.000"/>
      </material>
    </visual>
    <collision>
      <origin xyz="0 -0.003 0.019" rpy="0 0 0"/>
      <geometry>
        <box size="0.012 0.012 0.026"/>
      </geometry>
    </collision>
  </link>
  <link name="right_pinky_middle_link">
    <inertial>
      <origin xyz="1.1729e-08 -0.00110519 0.0093962" rpy="1.7272501e-05 0.054300862 1.5707963"/>
      <mass value="0.00237591"/>
      <inertia ixx="1.6252e-07" iyy="1.35575e-07" izz="7.42876e-08" ixy="0" ixz="0" iyz="0"/>
    </inertial>
    <visual>
      <origin xyz="0 0 0" rpy="0 0 0"/>
      <geometry>
        <mesh filename="package://g1_description/meshes/right_pinky_middle_link.STL"/>
      </geometry>
      <material name="mesh_mat">
        <color rgba="0.700 0.700 0.700 1.000"/>
      </material>
    </visual>
    <collision>
      <origin xyz="0 -0.001 0.006" rpy="0 0 0"/>
      <geometry>
        <box size="0.012 0.01 0.02"/>
      </geometry>
    </collision>
  </link>
  <link name="right_pinky_distal_link">
    <inertial>
      <origin xyz="-0.00184407 0.000358264 0.0107282" rpy="-0.19960648 0.33092209 1.5311051"/>
      <mass value="0.00309314"/>
      <inertia ixx="1.89076e-07" iyy="1.75557e-07" izz="6.3941e-08" ixy="0" ixz="0" iyz="0"/>
    </inertial>
    <visual>
      <origin xyz="0 0 0" rpy="0 0 0"/>
      <geometry>
        <mesh filename="package://g1_description/meshes/right_pinky_distal_link.STL"/>
      </geometry>
      <material name="mesh_mat">
        <color rgba="0.700 0.700 0.700 1.000"/>
      </material>
    </visual>
    <collision>
      <origin xyz="0 -0.003 0.014" rpy="0 0 0"/>
      <geometry>
        <box size="0.01 0.01 0.02"/>
      </geometry>
    </collision>
  </link>
  <link name="right_pinky_tip_link">
    <inertial>
      <origin xyz="2.46097e-08 -0.00705336 -0.0124437" rpy="0 0.28826641 1.5707974"/>
      <mass value="0.000390295"/>
      <inertia ixx="1.50784e-08" iyy="1.2527e-08" izz="7.70086e-09" ixy="0" ixz="0" iyz="0"/>
    </inertial>
    <visual>
      <origin xyz="0 0 0" rpy="0 0 0"/>
      <geometry>
        <mesh filename="package://g1_description/meshes/right_pinky_tip_link.STL"/>
      </geometry>
      <material name="mesh_mat">
        <color rgba="0.750 0.750 0.750 1.000"/>
      </material>
    </visual>
  </link>
  <link name="right_t_link">
    <inertial>
      <origin xyz="-0.000792597 0.00920489 0.00837042" rpy="-0.47620725 -0.078572407 0.15665522"/>
      <mass value="0.00893482"/>
      <inertia ixx="1.11708e-06" iyy="8.42419e-07" izz="4.36164e-07" ixy="0" ixz="0" iyz="0"/>
    </inertial>
    <visual>
      <origin xyz="0 0 0" rpy="0 0 0"/>
      <geometry>
        <mesh filename="package://g1_description/meshes/right_t_link.STL"/>
      </geometry>
      <material name="mesh_mat">
        <color rgba="0.700 0.700 0.700 1.000"/>
      </material>
    </visual>
    <collision>
      <origin xyz="-0.01 0.015 0.005" rpy="0 0 0"/>
      <geometry>
        <box size="0.03 0.016 0.016"/>
      </geometry>
    </collision>
  </link>
  <link name="right_thumb_mcp_link">
    <inertial>
      <origin xyz="-3.98621e-09 -0.0014303 0.0147562" rpy="-1.4315147e-05 -0.058078062 1.5707835"/>
      <mass value="0.0102694"/>
      <inertia ixx="1.58158e-06" iyy="1.39018e-06" izz="6.7267e-07" ixy="0" ixz="0" iyz="0"/>
    </inertial>
    <visual>
      <origin xyz="0 0 0" rpy="0 0 0"/>
      <geometry>
        <mesh filename="package://g1_description/meshes/right_thumb_mcp_link.STL"/>
      </geometry>
      <material name="mesh_mat">
        <color rgba="0.700 0.700 0.700 1.000"/>
      </material>
    </visual>
    <collision>
      <origin xyz="0 0 0.014" rpy="0 0 0"/>
      <geometry>
        <box size="0.016 0.02 0.032"/>
      </geometry>
    </collision>
  </link>
  <link name="right_thumb_proximal_link">
    <inertial>
      <origin xyz="-9.60413e-08 -0.00147723 0.0133935" rpy="2.1776953e-05 0.030493743 1.5707865"/>
      <mass value="0.00574573"/>
      <inertia ixx="6.77924e-07" iyy="5.00351e-07" izz="3.51862e-07" ixy="0" ixz="0" iyz="0"/>
    </inertial>
    <visual>
      <origin xyz="0 0 0" rpy="0 0 0"/>
      <geometry>
        <mesh filename="package://g1_description/meshes/right_thumb_proximal_link.STL"/>
      </geometry>
      <material name="mesh_mat">
        <color rgba="0.700 0.700 0.700 1.000"/>
      </material>
    </visual>
    <collision>
      <origin xyz="0 -0.002 0.012" rpy="0 0 0"/>
      <geometry>
        <box size="0.016 0.012 0.024"/>
      </geometry>
    </collision>
  </link>
  <link name="right_thumb_distal_link">
    <inertial>
      <origin xyz="-0.00113926 -0.00130909 0.0133464" rpy="-0.12885968 0.27095325 1.5547385"/>
      <mass value="0.00692863"/>
      <inertia ixx="6.65186e-07" iyy="5.66522e-07" izz="2.78338e-07" ixy="0" ixz="0" iyz="0"/>
    </inertial>
    <visual>
      <origin xyz="0 0 0" rpy="0 0 0"/>
      <geometry>
        <mesh filename="package://g1_description/meshes/right_thumb_distal_link.STL"/>
      </geometry>
      <material name="mesh_mat">
        <color rgba="0.700 0.700 0.700 1.000"/>
      </material>
    </visual>
    <collision>
      <origin xyz="0 -0.002 0.015" rpy="0 0 0"/>
      <geometry>
        <box size="0.016 0.012 0.024"/>
      </geometry>
    </collision>
  </link>
  <link name="right_thumb_tip_link">
    <inertial>
      <origin xyz="2.2383e-07 -0.010203 -0.013939" rpy="0.00041469501 0.3161801 1.5710172"/>
      <mass value="0.00086967"/>
      <inertia ixx="6.48507e-08" iyy="5.0257e-08" izz="3.56243e-08" ixy="0" ixz="0" iyz="0"/>
    </inertial>
    <visual>
      <origin xyz="0 0 0" rpy="0 0 0"/>
      <geometry>
        <mesh filename="package://g1_description/meshes/right_thumb_tip_link.STL"/>
      </geometry>
      <material name="mesh_mat">
        <color rgba="0.750 0.750 0.750 1.000"/>
      </material>
    </visual>
  </link>

  <joint name="floating_base_joint" type="floating">
    <parent link="world"/>
    <child link="pelvis"/>
    <origin xyz="0 0 0" rpy="0 0 0"/>
  </joint>
  <joint name="fixed_pelvis_contour_link" type="fixed">
    <parent link="pelvis"/>
    <child link="pelvis_contour_link"/>
    <origin xyz="0 0 0" rpy="0 0 0"/>
  </joint>
  <joint name="left_hip_pitch_joint" type="revolute">
    <parent link="pelvis"/>
    <child link="left_hip_pitch_link"/>
    <origin xyz="0 0.064452 -0.1027" rpy="0 0 0"/>
    <axis xyz="0 1 0"/>
    <limit lower="-2.5307" upper="2.8798" effort="88" velocity="10.0"/>
  </joint>
  <joint name="left_hip_roll_joint" type="revolute">
    <parent link="left_hip_pitch_link"/>
    <child link="left_hip_roll_link"/>
    <origin xyz="0 0.052 -0.030465" rpy="0 -0.1749001 0"/>
    <axis xyz="1 0 0"/>
    <limit lower="-0.5236" upper="2.9671" effort="139" velocity="10.0"/>
  </joint>
  <joint name="left_hip_yaw_joint" type="revolute">
    <parent link="left_hip_roll_link"/>
    <child link="left_hip_yaw_link"/>
    <origin xyz="0.025001 0 -0.12412" rpy="0 0 0"/>
    <axis xyz="0 0 1"/>
    <limit lower="-2.7576" upper="2.7576" effort="88" velocity="10.0"/>
  </joint>
  <joint name="left_knee_joint" type="revolute">
    <parent link="left_hip_yaw_link"/>
    <child link="left_knee_link"/>
    <origin xyz="-0.078273 0.0021489 -0.17734" rpy="0 0.1749001 0"/>
    <axis xyz="0 1 0"/>
    <limit lower="-0.087267" upper="2.8798" effort="139" velocity="10.0"/>
  </joint>
  <joint name="left_ankle_pitch_joint" type="revolute">
    <parent link="left_knee_link"/>
    <child link="left_ankle_pitch_link"/>
    <origin xyz="0 -9.4445e-05 -0.30001" rpy="0 0 0"/>
    <axis xyz="0 1 0"/>
    <limit lower="-0.87267" upper="0.5236" effort="50" velocity="10.0"/>
  </joint>
  <joint name="left_ankle_roll_joint" type="revolute">
    <parent link="left_ankle_pitch_link"/>
    <child link="left_ankle_roll_link"/>
    <origin xyz="0 0 -0.017558" rpy="0 0 0"/>
    <axis xyz="1 0 0"/>
    <limit lower="-0.2618" upper="0.2618" effort="50" velocity="10.0"/>
  </joint>
  <joint name="fixed_left_toe_link" type="fixed">
    <parent link="left_ankle_roll_link"/>
    <child link="left_toe_link"/>
    <origin xyz="0.12 0 -0.039" rpy="0 0 0"/>
  </joint>
  <joint name="right_hip_pitch_joint" type="revolute">
    <parent link="pelvis"/>
    <child link="right_hip_pitch_link"/>
    <origin xyz="0 -0.064452 -0.1027" rpy="0 0 0"/>
    <axis xyz="0 1 0"/>
    <limit lower="-2.5307" upper="2.8798" effort="88" velocity="10.0"/>
  </joint>
  <joint name="right_hip_roll_joint" type="revolute">
    <parent link="right_hip_pitch_link"/>
    <child link="right_hip_roll_link"/>
    <origin xyz="0 -0.052 -0.030465" rpy="0 -0.1749001 0"/>
    <axis xyz="1 0 0"/>
    <limit lower="-2.9671" upper="0.5236" effort="139" velocity="10.0"/>
  </joint>
  <joint name="right_hip_yaw_joint" type="revolute">
    <parent link="right_hip_roll_link"/>
    <child link="right_hip_yaw_link"/>
    <origin xyz="0.025001 0 -0.12412" rpy="0 0 0"/>
    <axis xyz="0 0 1"/>
    <limit lower="-2.7576" upper="2.7576" effort="88" velocity="10.0"/>
  </joint>
  <joint name="right_knee_joint" type="revolute">
    <parent link="right_hip_yaw_link"/>
    <child link="right_knee_link"/>
    <origin xyz="-0.078273 -0.0021489 -0.17734" rpy="0 0.1749001 0"/>
    <axis xyz="0 1 0"/>
    <limit lower="-0.087267" upper="2.8798" effort="139" velocity="10.0"/>
  </joint>
  <joint name="right_ankle_pitch_joint" type="revolute">
    <parent link="right_knee_link"/>
    <child link="right_ankle_pitch_link"/>
    <origin xyz="0 9.4445e-05 -0.30001" rpy="0 0 0"/>
    <axis xyz="0 1 0"/>
    <limit lower="-0.87267" upper="0.5236" effort="50" velocity="10.0"/>
  </joint>
  <joint name="right_ankle_roll_joint" type="revolute">
    <parent link="right_ankle_pitch_link"/>
    <child link="right_ankle_roll_link"/>
    <origin xyz="0 0 -0.017558" rpy="0 0 0"/>
    <axis xyz="1 0 0"/>
    <limit lower="-0.2618" upper="0.2618" effort="50" velocity="10.0"/>
  </joint>
  <joint name="fixed_right_toe_link" type="fixed">
    <parent link="right_ankle_roll_link"/>
    <child link="right_toe_link"/>
    <origin xyz="0.12 0 -0.039" rpy="0 0 0"/>
  </joint>
  <joint name="waist_yaw_joint" type="revolute">
    <parent link="pelvis"/>
    <child link="waist_yaw_link"/>
    <origin xyz="0 0 0" rpy="0 0 0"/>
    <axis xyz="0 0 1"/>
    <limit lower="-2.618" upper="2.618" effort="88" velocity="10.0"/>
  </joint>
  <joint name="waist_roll_joint" type="revolute">
    <parent link="waist_yaw_link"/>
    <child link="waist_roll_link"/>
    <origin xyz="-0.0039635 0 0.044" rpy="0 0 0"/>
    <axis xyz="1 0 0"/>
    <limit lower="-0.52" upper="0.52" effort="50" velocity="10.0"/>
  </joint>
  <joint name="waist_pitch_joint" type="revolute">
    <parent link="waist_roll_link"/>
    <child link="torso_link"/>
    <origin xyz="0 0 0" rpy="0 0 0"/>
    <axis xyz="0 1 0"/>
    <limit lower="-0.52" upper="0.52" effort="50" velocity="10.0"/>
  </joint>
  <joint name="fixed_head_link" type="fixed">
    <parent link="torso_link"/>
    <child link="head_link"/>
    <origin xyz="0.0039635 0 -0.044" rpy="0 0 0"/>
  </joint>
  <joint name="fixed_head_mocap" type="fixed">
    <parent link="torso_link"/>
    <child link="head_mocap"/>
    <origin xyz="0 0 0.4" rpy="0 0 0"/>
  </joint>
  <joint name="fixed_neck_link" type="fixed">
    <parent link="head_mocap"/>
    <child link="neck_link"/>
    <origin xyz="0.05 0.02 0.075" rpy="1.5707969 -0 0"/>
  </joint>
  <joint name="fixed_imu_in_torso" type="fixed">
    <parent link="torso_link"/>
    <child link="imu_in_torso"/>
    <origin xyz="-0.03959 -0.00224 0.14792" rpy="0 0 0"/>
  </joint>
  <joint name="left_shoulder_pitch_joint" type="revolute">
    <parent link="torso_link"/>
    <child link="left_shoulder_pitch_link"/>
    <origin xyz="0.0039563 0.10022 0.24778" rpy="0.27930898 5.4948883e-05 -0.00019158992"/>
    <axis xyz="0 1 0"/>
    <limit lower="-3.0892" upper="2.6704" effort="25" velocity="10.0"/>
  </joint>
  <joint name="left_shoulder_roll_joint" type="revolute">
    <parent link="left_shoulder_pitch_link"/>
    <child link="left_shoulder_roll_link"/>
    <origin xyz="0 0.038 -0.013831" rpy="-0.2792504 0 0"/>
    <axis xyz="1 0 0"/>
    <limit lower="-1.5882" upper="2.2515" effort="25" velocity="10.0"/>
  </joint>
  <joint name="left_shoulder_yaw_joint" type="revolute">
    <parent link="left_shoulder_roll_link"/>
    <child link="left_shoulder_yaw_link"/>
    <origin xyz="0 0.00624 -0.1032" rpy="0 0 0"/>
    <axis xyz="0 0 1"/>
    <limit lower="-2.618" upper="2.618" effort="25" velocity="10.0"/>
  </joint>
  <joint name="left_elbow_joint" type="revolute">
    <parent link="left_shoulder_yaw_link"/>
    <child link="left_elbow_link"/>
    <origin xyz="0.015783 0 -0.080518" rpy="0 0 0"/>
    <axis xyz="0 1 0"/>
    <limit lower="-1.0472" upper="2.0944" effort="25" velocity="10.0"/>
  </joint>
  <joint name="left_wrist_roll_joint" type="revolute">
    <parent link="left_elbow_link"/>
    <child link="left_wrist_roll_link"/>
    <origin xyz="0.1 0.00188791 -0.01" rpy="0 0 0"/>
    <axis xyz="1 0 0"/>
    <limit lower="-1.97222" upper="1.97222" effort="25" velocity="10.0"/>
  </joint>
  <joint name="left_wrist_pitch_joint" type="revolute">
    <parent link="left_wrist_roll_link"/>
    <child link="left_wrist_pitch_link"/>
    <origin xyz="0.038 0 0" rpy="0 0 0"/>
    <axis xyz="0 1 0"/>
    <limit lower="-1.61443" upper="1.61443" effort="5" velocity="10.0"/>
  </joint>
  <joint name="left_wrist_yaw_joint" type="revolute">
    <parent link="left_wrist_pitch_link"/>
    <child link="left_wrist_yaw_link"/>
    <origin xyz="0.046 0 0" rpy="0 0 0"/>
    <axis xyz="0 0 1"/>
    <limit lower="-1.61443" upper="1.61443" effort="5" velocity="10.0"/>
  </joint>
  <joint name="fixed_left_base_link" type="fixed">
    <parent link="left_wrist_yaw_link"/>
    <child link="left_base_link"/>
    <origin xyz="0.0415 0.003 0" rpy="0 1.5694152 0"/>
  </joint>
  <joint name="fixed_left_index_f_link" type="fixed">
    <parent link="left_base_link"/>
    <child link="left_index_f_link"/>
    <origin xyz="-0.031448 -0.004172 0.10003" rpy="1.9906982e-09 -0.052359951 0.034906931"/>
  </joint>
  <joint name="left_index_mcp_flex" type="revolute">
    <parent link="left_index_f_link"/>
    <child link="left_index_proximal_link"/>
    <origin xyz="0 0 0.0034" rpy="0 0 0"/>
    <axis xyz="1 0 0"/>
    <limit lower="0" upper="1.5708" effort="0" velocity="10.0"/>
  </joint>
  <joint name="left_index_pip" type="revolute">
    <parent link="left_index_proximal_link"/>
    <child link="left_index_middle_link"/>
    <origin xyz="0 -0.0014554 0.043" rpy="0.017453003 -0 0"/>
    <axis xyz="1 0 0"/>
    <limit lower="0" upper="1.5708" effort="0" velocity="10.0"/>
  </joint>
  <joint name="left_index_dip" type="revolute">
    <parent link="left_index_middle_link"/>
    <child link="left_index_distal_link"/>
    <origin xyz="0 0.00036966 0.021997" rpy="0.0010587002 -0 0"/>
    <axis xyz="1 0 0"/>
    <limit lower="0" upper="1.5708" effort="0" velocity="10.0"/>
  </joint>
  <joint name="fixed_left_index_tip_link" type="fixed">
    <parent link="left_index_distal_link"/>
    <child link="left_index_tip_link"/>
    <origin xyz="0 0.003512 0.026776" rpy="0 0 -4.10206e-10"/>
  </joint>
  <joint name="fixed_left_middle_f_link" type="fixed">
    <parent link="left_base_link"/>
    <child link="left_middle_f_link"/>
    <origin xyz="-0.0085 -0.003 0.10061" rpy="0 0 0"/>
  </joint>
  <joint name="left_middle_mcp_flex" type="revolute">
    <parent link="left_middle_f_link"/>
    <child link="left_middle_proximal_link"/>
    <origin xyz="0 0 0.0034" rpy="0 0 0"/>
    <axis xyz="1 0 0"/>
    <limit lower="0" upper="1.5708" effort="0" velocity="10.0"/>
  </joint>
  <joint name="left_middle_pip" type="revolute">
    <parent link="left_middle_proximal_link"/>
    <child link="left_middle_middle_link"/>
    <origin xyz="0 -0.0014554 0.043" rpy="0.017453003 -0 0"/>
    <axis xyz="1 0 0"/>
    <limit lower="0" upper="1.5708" effort="0" velocity="10.0"/>
  </joint>
  <joint name="left_middle_dip" type="revolute">
    <parent link="left_middle_middle_link"/>
    <child link="left_middle_distal_link"/>
    <origin xyz="0 0.00036966 0.021997" rpy="0.0010587002 -0 0"/>
    <axis xyz="1 0 0"/>
    <limit lower="0" upper="1.5708" effort="0" velocity="10.0"/>
  </joint>
  <joint name="fixed_left_middle_tip_link" type="fixed">
    <parent link="left_middle_distal_link"/>
    <child link="left_middle_tip_link"/>
    <origin xyz="0 0.003512 0.026776" rpy="0 0 -4.10206e-10"/>
  </joint>
  <joint name="fixed_left_ring_f_link" type="fixed">
    <parent link="left_base_link"/>
    <child link="left_ring_f_link"/>
    <origin xyz="0.014448 -0.004172 0.10003" rpy="1.9906982e-09 0.052359951 -0.034906931"/>
  </joint>
  <joint name="left_ring_mcp_flex" type="revolute">
    <parent link="left_ring_f_link"/>
    <child link="left_ring_proximal_link"/>
    <origin xyz="0 0 0.0034" rpy="0 0 0"/>
    <axis xyz="1 0 0"/>
    <limit lower="0" upper="1.5708" effort="0" velocity="10.0"/>
  </joint>
  <joint name="left_ring_pip" type="revolute">
    <parent link="left_ring_proximal_link"/>
    <child link="left_ring_middle_link"/>
    <origin xyz="0 -0.0014554 0.043" rpy="0.017453003 -0 0"/>
    <axis xyz="1 0 0"/>
    <limit lower="0" upper="1.5708" effort="0" velocity="10.0"/>
  </joint>
  <joint name="left_ring_dip" type="revolute">
    <parent link="left_ring_middle_link"/>
    <child link="left_ring_distal_link"/>
    <origin xyz="0 0.00036966 0.021997" rpy="0.0010587002 -0 0"/>
    <axis xyz="1 0 0"/>
    <limit lower="0" upper="1.5708" effort="0" velocity="10.0"/>
  </joint>
  <joint name="fixed_left_ring_tip_link" type="fixed">
    <parent link="left_ring_distal_link"/>
    <child link="left_ring_tip_link"/>
    <origin xyz="0 0.003512 0.026776" rpy="0 0 -4.10206e-10"/>
  </joint>
  <joint name="fixed_left_pinky_f_link" type="fixed">
    <parent link="left_base_link"/>
    <child link="left_pinky_f_link"/>
    <origin xyz="0.036912 -0.0066167 0.087021" rpy="4.9434811e-10 0.10472006 -0.069946107"/>
  </joint>
  <joint name="left_pinky_mcp_flex" type="revolute">
    <parent link="left_pinky_f_link"/>
    <child link="left_pinky_proximal_link"/>
    <origin xyz="0 0 0.0034" rpy="0 0 0"/>
    <axis xyz="1 0 0"/>
    <limit lower="0" upper="1.5708" effort="0" velocity="10.0"/>
  </joint>
  <joint name="left_pinky_pip" type="revolute">
    <parent link="left_pinky_proximal_link"/>
    <child link="left_pinky_middle_link"/>
    <origin xyz="0 -0.0014554 0.043" rpy="0.017453003 -0 0"/>
    <axis xyz="1 0 0"/>
    <limit lower="0" upper="1.5708" effort="0" velocity="10.0"/>
  </joint>
  <joint name="left_pinky_dip" type="revolute">
    <parent link="left_pinky_middle_link"/>
    <child link="left_pinky_distal_link"/>
    <origin xyz="0 0.00036966 0.021997" rpy="0.0010587002 -0 0"/>
    <axis xyz="1 0 0"/>
    <limit lower="0" upper="1.5708" effort="0" velocity="10.0"/>
  </joint>
  <joint name="fixed_left_pinky_tip_link" type="fixed">
    <parent link="left_pinky_distal_link"/>
    <child link="left_pinky_tip_link"/>
    <origin xyz="0 0.003512 0.026776" rpy="0 0 -4.10206e-10"/>
  </joint>
  <joint name="left_thumb_cmc_abd" type="revolute">
    <parent link="left_base_link"/>
    <child link="left_t_link"/>
    <origin xyz="-0.026317 -0.0175 0.02956" rpy="-1.2217001 -6.94652e-07 1.5708"/>
    <axis xyz="0 -1 0"/>
    <limit lower="0" upper="1.7453" effort="0" velocity="10.0"/>
  </joint>
  <joint name="left_thumb_cmc_flex" type="revolute">
    <parent link="left_t_link"/>
    <child link="left_thumb_mcp_link"/>
    <origin xyz="0.0024625 0.011988 0.019805" rpy="0.089750033 0.12949009 -0.25989016"/>
    <axis xyz="1 0 0"/>
    <limit lower="0" upper="0.9559" effort="0" velocity="10.0"/>
  </joint>
  <joint name="left_thumb_mcp" type="revolute">
    <parent link="left_thumb_mcp_link"/>
    <child link="left_thumb_proximal_link"/>
    <origin xyz="0 0.0013652 0.035982" rpy="0 0 0"/>
    <axis xyz="1 0 0"/>
    <limit lower="0" upper="1.5708" effort="0" velocity="10.0"/>
  </joint>
  <joint name="left_thumb_ip" type="revolute">
    <parent link="left_thumb_proximal_link"/>
    <child link="left_thumb_distal_link"/>
    <origin xyz="0 0.00052357 0.029995" rpy="0 0 0"/>
    <axis xyz="1 0 0"/>
    <limit lower="0" upper="1.5708" effort="0" velocity="10.0"/>
  </joint>
  <joint name="fixed_left_thumb_tip_link" type="fixed">
    <parent link="left_thumb_distal_link"/>
    <child link="left_thumb_tip_link"/>
    <origin xyz="0 0.0059474 0.031823" rpy="0 0 -4.10206e-10"/>
  </joint>
  <joint name="right_shoulder_pitch_joint" type="revolute">
    <parent link="torso_link"/>
    <child link="right_shoulder_pitch_link"/>
    <origin xyz="0.0039563 -0.10021 0.24778" rpy="-0.27930898 5.4948883e-05 0.00019158992"/>
    <axis xyz="0 1 0"/>
    <limit lower="-3.0892" upper="2.6704" effort="25" velocity="10.0"/>
  </joint>
  <joint name="right_shoulder_roll_joint" type="revolute">
    <parent link="right_shoulder_pitch_link"/>
    <child link="right_shoulder_roll_link"/>
    <origin xyz="0 -0.038 -0.013831" rpy="0.2792504 -0 0"/>
    <axis xyz="1 0 0"/>
    <limit lower="-2.2515" upper="1.5882" effort="25" velocity="10.0"/>
  </joint>
  <joint name="right_shoulder_yaw_joint" type="revolute">
    <parent link="right_shoulder_roll_link"/>
    <child link="right_shoulder_yaw_link"/>
    <origin xyz="0 -0.00624 -0.1032" rpy="0 0 0"/>
    <axis xyz="0 0 1"/>
    <limit lower="-2.618" upper="2.618" effort="25" velocity="10.0"/>
  </joint>
  <joint name="right_elbow_joint" type="revolute">
    <parent link="right_shoulder_yaw_link"/>
    <child link="right_elbow_link"/>
    <origin xyz="0.015783 0 -0.080518" rpy="0 0 0"/>
    <axis xyz="0 1 0"/>
    <limit lower="-1.0472" upper="2.0944" effort="25" velocity="10.0"/>
  </joint>
  <joint name="right_wrist_roll_joint" type="revolute">
    <parent link="right_elbow_link"/>
    <child link="right_wrist_roll_link"/>
    <origin xyz="0.1 -0.00188791 -0.01" rpy="0 0 0"/>
    <axis xyz="1 0 0"/>
    <limit lower="-1.97222" upper="1.97222" effort="25" velocity="10.0"/>
  </joint>
  <joint name="right_wrist_pitch_joint" type="revolute">
    <parent link="right_wrist_roll_link"/>
    <child link="right_wrist_pitch_link"/>
    <origin xyz="0.038 0 0" rpy="0 0 0"/>
    <axis xyz="0 1 0"/>
    <limit lower="-1.61443" upper="1.61443" effort="5" velocity="10.0"/>
  </joint>
  <joint name="right_wrist_yaw_joint" type="revolute">
    <parent link="right_wrist_pitch_link"/>
    <child link="right_wrist_yaw_link"/>
    <origin xyz="0.046 0 0" rpy="0 0 0"/>
    <axis xyz="0 0 1"/>
    <limit lower="-1.61443" upper="1.61443" effort="5" velocity="10.0"/>
  </joint>
  <joint name="fixed_right_base_link" type="fixed">
    <parent link="right_wrist_yaw_link"/>
    <child link="right_base_link"/>
    <origin xyz="0.0415 -0.003 0" rpy="-5.8987815e-07 -1.5699967 3.1400006"/>
  </joint>
  <joint name="fixed_right_index_f_link" type="fixed">
    <parent link="right_base_link"/>
    <child link="right_index_f_link"/>
    <origin xyz="0.031448 -0.004172 0.10003" rpy="1.9906982e-09 0.052359951 -0.034906931"/>
  </joint>
  <joint name="right_index_mcp_flex" type="revolute">
    <parent link="right_index_f_link"/>
    <child link="right_index_proximal_link"/>
    <origin xyz="0 0 0.0034" rpy="0 0 0"/>
    <axis xyz="1 0 0"/>
    <limit lower="0" upper="1.5708" effort="0" velocity="10.0"/>
  </joint>
  <joint name="right_index_pip" type="revolute">
    <parent link="right_index_proximal_link"/>
    <child link="right_index_middle_link"/>
    <origin xyz="0 -0.0014554 0.043" rpy="0.017453003 -0 0"/>
    <axis xyz="1 0 0"/>
    <limit lower="0" upper="1.5708" effort="0" velocity="10.0"/>
  </joint>
  <joint name="right_index_dip" type="revolute">
    <parent link="right_index_middle_link"/>
    <child link="right_index_distal_link"/>
    <origin xyz="0 0.00036966 0.021997" rpy="0.0010587002 -0 0"/>
    <axis xyz="1 0 0"/>
    <limit lower="0" upper="1.5708" effort="0" velocity="10.0"/>
  </joint>
  <joint name="fixed_right_index_tip_link" type="fixed">
    <parent link="right_index_distal_link"/>
    <child link="right_index_tip_link"/>
    <origin xyz="0 0.003512 0.026776" rpy="0 0 0"/>
  </joint>
  <joint name="fixed_right_middle_f_link" type="fixed">
    <parent link="right_base_link"/>
    <child link="right_middle_f_link"/>
    <origin xyz="0.0085 -0.003 0.10061" rpy="0 0 0"/>
  </joint>
  <joint name="right_middle_mcp_flex" type="revolute">
    <parent link="right_middle_f_link"/>
    <child link="right_middle_proximal_link"/>
    <origin xyz="0 0 0.0034" rpy="0 0 0"/>
    <axis xyz="1 0 0"/>
    <limit lower="0" upper="1.5708" effort="0" velocity="10.0"/>
  </joint>
  <joint name="right_middle_pip" type="revolute">
    <parent link="right_middle_proximal_link"/>
    <child link="right_middle_middle_link"/>
    <origin xyz="0 -0.0014554 0.043" rpy="0.017453003 -0 0"/>
    <axis xyz="1 0 0"/>
    <limit lower="0" upper="1.5708" effort="0" velocity="10.0"/>
  </joint>
  <joint name="right_middle_dip" type="revolute">
    <parent link="right_middle_middle_link"/>
    <child link="right_middle_distal_link"/>
    <origin xyz="0 0.00036966 0.021997" rpy="0.0010587002 -0 0"/>
    <axis xyz="1 0 0"/>
    <limit lower="0" upper="1.5708" effort="0" velocity="10.0"/>
  </joint>
  <joint name="fixed_right_middle_tip_link" type="fixed">
    <parent link="right_middle_distal_link"/>
    <child link="right_middle_tip_link"/>
    <origin xyz="0 0.003512 0.026776" rpy="0 0 0"/>
  </joint>
  <joint name="fixed_right_ring_f_link" type="fixed">
    <parent link="right_base_link"/>
    <child link="right_ring_f_link"/>
    <origin xyz="-0.014448 -0.004172 0.10003" rpy="1.9906982e-09 -0.052359951 0.034906931"/>
  </joint>
  <joint name="right_ring_mcp_flex" type="revolute">
    <parent link="right_ring_f_link"/>
    <child link="right_ring_proximal_link"/>
    <origin xyz="0 0 0.0034" rpy="0 0 0"/>
    <axis xyz="1 0 0"/>
    <limit lower="0" upper="1.5708" effort="0" velocity="10.0"/>
  </joint>
  <joint name="right_ring_pip" type="revolute">
    <parent link="right_ring_proximal_link"/>
    <child link="right_ring_middle_link"/>
    <origin xyz="0 -0.0014554 0.043" rpy="0.017453003 -0 0"/>
    <axis xyz="1 0 0"/>
    <limit lower="0" upper="1.5708" effort="0" velocity="10.0"/>
  </joint>
  <joint name="right_ring_dip" type="revolute">
    <parent link="right_ring_middle_link"/>
    <child link="right_ring_distal_link"/>
    <origin xyz="0 0.00036966 0.021997" rpy="0.0010587002 -0 0"/>
    <axis xyz="1 0 0"/>
    <limit lower="0" upper="1.5708" effort="0" velocity="10.0"/>
  </joint>
  <joint name="fixed_right_ring_tip_link" type="fixed">
    <parent link="right_ring_distal_link"/>
    <child link="right_ring_tip_link"/>
    <origin xyz="0 0.003512 0.026776" rpy="0 0 0"/>
  </joint>
  <joint name="fixed_right_pinky_f_link" type="fixed">
    <parent link="right_base_link"/>
    <child link="right_pinky_f_link"/>
    <origin xyz="-0.036912 -0.0066167 0.087021" rpy="4.9434811e-10 -0.10472006 0.069946107"/>
  </joint>
  <joint name="right_pinky_mcp_flex" type="revolute">
    <parent link="right_pinky_f_link"/>
    <child link="right_pinky_proximal_link"/>
    <origin xyz="0 0 0.0034" rpy="0 0 0"/>
    <axis xyz="1 0 0"/>
    <limit lower="0" upper="1.5708" effort="0" velocity="10.0"/>
  </joint>
  <joint name="right_pinky_pip" type="revolute">
    <parent link="right_pinky_proximal_link"/>
    <child link="right_pinky_middle_link"/>
    <origin xyz="0 -0.0014554 0.043" rpy="0.017453003 -0 0"/>
    <axis xyz="1 0 0"/>
    <limit lower="0" upper="1.5708" effort="0" velocity="10.0"/>
  </joint>
  <joint name="right_pinky_dip" type="revolute">
    <parent link="right_pinky_middle_link"/>
    <child link="right_pinky_distal_link"/>
    <origin xyz="0 0.00036966 0.021997" rpy="0.0010587002 -0 0"/>
    <axis xyz="1 0 0"/>
    <limit lower="0" upper="1.5708" effort="0" velocity="10.0"/>
  </joint>
  <joint name="fixed_right_pinky_tip_link" type="fixed">
    <parent link="right_pinky_distal_link"/>
    <child link="right_pinky_tip_link"/>
    <origin xyz="0 0.003512 0.026776" rpy="0 0 0"/>
  </joint>
  <joint name="right_thumb_cmc_abd" type="revolute">
    <parent link="right_base_link"/>
    <child link="right_t_link"/>
    <origin xyz="0.026317 -0.0175 0.02956" rpy="-1.2217001 6.94652e-07 -1.5708"/>
    <axis xyz="0 1 0"/>
    <limit lower="0" upper="1.7453" effort="0" velocity="10.0"/>
  </joint>
  <joint name="right_thumb_cmc_flex" type="revolute">
    <parent link="right_t_link"/>
    <child link="right_thumb_mcp_link"/>
    <origin xyz="-0.0024625 0.011988 0.019805" rpy="0.089750033 -0.12949009 0.25989016"/>
    <axis xyz="1 0 0"/>
    <limit lower="0" upper="0.9559" effort="0" velocity="10.0"/>
  </joint>
  <joint name="right_thumb_mcp" type="revolute">
    <parent link="right_thumb_mcp_link"/>
    <child link="right_thumb_proximal_link"/>
    <origin xyz="0 0.0013652 0.035982" rpy="0 0 0"/>
    <axis xyz="1 0 0"/>
    <limit lower="0" upper="1.5708" effort="0" velocity="10.0"/>
  </joint>
  <joint name="right_thumb_ip" type="revolute">
    <parent link="right_thumb_proximal_link"/>
    <child link="right_thumb_distal_link"/>
    <origin xyz="0 0.00052357 0.029995" rpy="0 0 0"/>
    <axis xyz="1 0 0"/>
    <limit lower="0" upper="1.5708" effort="0" velocity="10.0"/>
  </joint>
  <joint name="fixed_right_thumb_tip_link" type="fixed">
    <parent link="right_thumb_distal_link"/>
    <child link="right_thumb_tip_link"/>
    <origin xyz="0 0.0059474 0.031823" rpy="0 0 0"/>
  </joint>

</robot>